Workbook

Sheet PEDIDOS
A1: OP | B1: Fecha | C1: N° OC | D1: CLIENTE | E1: PRODUCTO | F1: S | G1: Q | H1: Ml | I1: ESTADO | M1: N° LOTE
A2: 25293 | B2: 46035 | C2: 163 | D2: THE MINIMAL CO | E2: MILKY TONER | F2: P | G2: 900 | H2: 100 | I2: =IF(OR(L2="entregado",K2="despacho",J2="en proceso"),"","ingreso") | J2: =IF(OR(L2="entregado",K2="despacho"),"", IF(AND(ELABORACION!F2<>"-",ELABORACION!F2<>"PENDIENTE ELAB"),"en proceso","")) | K2: =IF(L2="entregado","",IF(EXPEDICION!L2="listo para entregar","despacho","")) | L2: =IF(EXPEDICION!L2="entregado", "entregado", "") -> entregado | M2: =EXPEDICION!M2 -> F26021
A3: 25294 | B3: 46035 | C3: 14297 | D3: JACTANS | E3: JS-941 AGUA MICELAR BIFASCIA | F3: P | G3: 1000 | H3: 105 | I3: =IF(OR(L3="entregado",K3="despacho",J3="en proceso"),"","ingreso") | J3: =IF(OR(L3="entregado",K3="despacho"),"", IF(AND(ELABORACION!F3<>"-",ELABORACION!F3<>"PENDIENTE ELAB"),"en proceso","")) | K3: =IF(L3="entregado","",IF(EXPEDICION!L3="listo para entregar","despacho","")) | L3: =IF(EXPEDICION!L3="entregado", "entregado", "") -> entregado | M3: =EXPEDICION!M3 -> F26031
A4: 25295 | B4: 46035 | C4: 15074 | D4: THELMA Y LOUISE | E4: AGUA TERMAL | F4: P | G4: 2940 | H4: 100 | I4: =IF(OR(L4="entregado",K4="despacho",J4="en proceso"),"","ingreso") | J4: =IF(OR(L4="entregado",K4="despacho"),"", IF(AND(ELABORACION!F4<>"-",ELABORACION!F4<>"PENDIENTE ELAB"),"en proceso","")) | K4: =IF(L4="entregado","",IF(EXPEDICION!L4="listo para entregar","despacho","")) | L4: =IF(EXPEDICION!L4="entregado", "entregado", "") -> entregado | M4: =EXPEDICION!M4 -> F26041
A5: 25296 | B5: 46035 | D5: LIORA | E5: CREMA PARA PEINAR RULOS | F5: P | G5: 170 | H5: 300 | I5: =IF(OR(L5="entregado",K5="despacho",J5="en proceso"),"","ingreso") | J5: =IF(OR(L5="entregado",K5="despacho"),"", IF(AND(ELABORACION!F5<>"-",ELABORACION!F5<>"PENDIENTE ELAB"),"en proceso","")) | K5: =IF(L5="entregado","",IF(EXPEDICION!L5="listo para entregar","despacho","")) | L5: =IF(EXPEDICION!L5="entregado", "entregado", "") -> entregado | M5: =EXPEDICION!M5 -> Y26039
A6: 25298 | B6: 46042 | C6: P01203 | D6: BIOESENCIA | E6: SERUM ORIGENES | F6: P | G6: 1600 | H6: 30 | I6: =IF(OR(L6="entregado",K6="despacho",J6="en proceso"),"","ingreso") | J6: =IF(OR(L6="entregado",K6="despacho"),"", IF(AND(ELABORACION!F6<>"-",ELABORACION!F6<>"PENDIENTE ELAB"),"en proceso","")) | K6: =IF(L6="entregado","",IF(EXPEDICION!L6="listo para entregar","despacho","")) | L6: =IF(EXPEDICION!L6="entregado", "entregado", "") -> entregado | M6: =EXPEDICION!M6 -> 240201
A7: 25299 | B7: 46042 | D7: WSABI | E7: SERUM INTIMO | F7: P | G7: 300 | H7: 30 | I7: =IF(OR(L7="entregado",K7="despacho",J7="en proceso"),"","ingreso") | J7: =IF(OR(L7="entregado",K7="despacho"),"", IF(AND(ELABORACION!F7<>"-",ELABORACION!F7<>"PENDIENTE ELAB"),"en proceso","")) | K7: =IF(L7="entregado","",IF(EXPEDICION!L7="listo para entregar","despacho","")) | L7: =IF(EXPEDICION!L7="entregado", "entregado", "") -> entregado | M7: =EXPEDICION!M7 -> F26049
A8: 25300 | B8: 46042 | D8: MERMER | E8: ACEITE CORPORAL LAVANDA | F8: P | G8: 300 | H8: 200 | I8: =IF(OR(L8="entregado",K8="despacho",J8="en proceso"),"","ingreso") | J8: =IF(OR(L8="entregado",K8="despacho"),"", IF(AND(ELABORACION!F8<>"-",ELABORACION!F8<>"PENDIENTE ELAB"),"en proceso","")) | K8: =IF(L8="entregado","",IF(EXPEDICION!L8="listo para entregar","despacho","")) | L8: =IF(EXPEDICION!L8="entregado", "entregado", "") -> entregado | M8: =EXPEDICION!M8 -> E26087
A9: 25300 | B9: 46042 | D9: MERMER | E9: ACEITE CORPORAL ALMENDRA | F9: P | G9: 300 | H9: 200 | I9: =IF(OR(L9="entregado",K9="despacho",J9="en proceso"),"","ingreso") | J9: =IF(OR(L9="entregado",K9="despacho"),"", IF(AND(ELABORACION!F9<>"-",ELABORACION!F9<>"PENDIENTE ELAB"),"en proceso","")) | K9: =IF(L9="entregado","",IF(EXPEDICION!L9="listo para entregar","despacho","")) | L9: =IF(EXPEDICION!L9="entregado", "entregado", "") -> entregado | M9: =EXPEDICION!M9 -> E26088
A10: 25300 | B10: 46042 | D10: MERMER | E10: ACEITE CORPORAL ROSAS | F10: P | G10: 300 | H10: 200 | I10: =IF(OR(L10="entregado",K10="despacho",J10="en proceso"),"","ingreso") | J10: =IF(OR(L10="entregado",K10="despacho"),"", IF(AND(ELABORACION!F10<>"-",ELABORACION!F10<>"PENDIENTE ELAB"),"en proceso","")) | K10: =IF(L10="entregado","",IF(EXPEDICION!L10="listo para entregar","despacho","")) | L10: =IF(EXPEDICION!L10="entregado", "entregado", "") -> entregado | M10: =EXPEDICION!M10 -> E26089
A11: 25300 | B11: 46042 | D11: MERMER | E11: ACEITE CORPORAL SESAMO | F11: P | G11: 300 | H11: 200 | I11: =IF(OR(L11="entregado",K11="despacho",J11="en proceso"),"","ingreso") | J11: =IF(OR(L11="entregado",K11="despacho"),"", IF(AND(ELABORACION!F11<>"-",ELABORACION!F11<>"PENDIENTE ELAB"),"en proceso","")) | K11: =IF(L11="entregado","",IF(EXPEDICION!L11="listo para entregar","despacho","")) | L11: =IF(EXPEDICION!L11="entregado", "entregado", "") -> entregado | M11: =EXPEDICION!M11 -> E26090
A12: 25300 | B12: 46042 | D12: MERMER | E12: ACEITE CORPORAL INCIENSO | F12: P | G12: 300 | H12: 200 | I12: =IF(OR(L12="entregado",K12="despacho",J12="en proceso"),"","ingreso") | J12: =IF(OR(L12="entregado",K12="despacho"),"", IF(AND(ELABORACION!F12<>"-",ELABORACION!F12<>"PENDIENTE ELAB"),"en proceso","")) | K12: =IF(L12="entregado","",IF(EXPEDICION!L12="listo para entregar","despacho","")) | L12: =IF(EXPEDICION!L12="entregado", "entregado", "") -> entregado | M12: =EXPEDICION!M12 -> E26091
A13: 25300 | B13: 46042 | D13: MERMER | E13: ACEITE CORPORAL ARNICA | F13: P | G13: 300 | H13: 200 | I13: =IF(OR(L13="entregado",K13="despacho",J13="en proceso"),"","ingreso") | J13: =IF(OR(L13="entregado",K13="despacho"),"", IF(AND(ELABORACION!F13<>"-",ELABORACION!F13<>"PENDIENTE ELAB"),"en proceso","")) | K13: =IF(L13="entregado","",IF(EXPEDICION!L13="listo para entregar","despacho","")) | L13: =IF(EXPEDICION!L13="entregado", "entregado", "") -> entregado | M13: =EXPEDICION!M13 -> E26092
A14: 25300 | B14: 46042 | D14: MERMER | E14: LOCION CAPILAR | F14: P | G14: 400 | H14: 100 | I14: =IF(OR(L14="entregado",K14="despacho",J14="en proceso"),"","ingreso") | J14: =IF(OR(L14="entregado",K14="despacho"),"", IF(AND(ELABORACION!F14<>"-",ELABORACION!F14<>"PENDIENTE ELAB"),"en proceso","")) | K14: =IF(L14="entregado","",IF(EXPEDICION!L14="listo para entregar","despacho","")) | L14: =IF(EXPEDICION!L14="entregado", "entregado", "") -> entregado | M14: =EXPEDICION!M14 -> M26042
A15: 25300 | B15: 46042 | D15: MERMER | E15: SERUM CAPILAR | F15: P | G15: 400 | H15: 100 | I15: =IF(OR(L15="entregado",K15="despacho",J15="en proceso"),"","ingreso") | J15: =IF(OR(L15="entregado",K15="despacho"),"", IF(AND(ELABORACION!F15<>"-",ELABORACION!F15<>"PENDIENTE ELAB"),"en proceso","")) | K15: =IF(L15="entregado","",IF(EXPEDICION!L15="listo para entregar","despacho","")) | L15: =IF(EXPEDICION!L15="entregado", "entregado", "") -> entregado | M15: =EXPEDICION!M15 -> M26030
A16: 25301 | B16: 46049 | C16: 1708 | D16: LABORATORIO ONCE | E16: SERUM ACIDO HIALURONICO + NIACINAMIDA | F16: P | G16: 1653 | H16: 30 | I16: =IF(OR(L16="entregado",K16="despacho",J16="en proceso"),"","ingreso") | J16: =IF(OR(L16="entregado",K16="despacho"),"", IF(AND(ELABORACION!F16<>"-",ELABORACION!F16<>"PENDIENTE ELAB"),"en proceso","")) | K16: =IF(L16="entregado","",IF(EXPEDICION!L16="listo para entregar","despacho","")) | L16: =IF(EXPEDICION!L16="entregado", "entregado", "") -> entregado | M16: =EXPEDICION!M16 -> F26048
A17: 25302 | B17: 46050 | C17: 15098 | D17: THELMA Y LOUISE | E17: CREMA BIFASICA CHERRY | F17: M | G17: 1640 | H17: 160 | I17: =IF(OR(L17="entregado",K17="despacho",J17="en proceso"),"","ingreso") | J17: =IF(OR(L17="entregado",K17="despacho"),"", IF(AND(ELABORACION!F17<>"-",ELABORACION!F17<>"PENDIENTE ELAB"),"en proceso","")) | K17: =IF(L17="entregado","",IF(EXPEDICION!L17="listo para entregar","despacho","")) | L17: =IF(EXPEDICION!L17="entregado", "entregado", "") -> entregado | M17: =EXPEDICION!M17
A18: 25303 | B18: 46052 | D18: ALL BEAUTY | E18: SERUM ACIDO HIALURONICO | F18: P | G18: 1000 | H18: 30 | I18: =IF(OR(L18="entregado",K18="despacho",J18="en proceso"),"","ingreso") | J18: =IF(OR(L18="entregado",K18="despacho"),"", IF(AND(ELABORACION!F18<>"-",ELABORACION!F18<>"PENDIENTE ELAB"),"en proceso","")) | K18: =IF(L18="entregado","",IF(EXPEDICION!L18="listo para entregar","despacho","")) | L18: =IF(EXPEDICION!L18="entregado", "entregado", "") -> entregado | M18: =EXPEDICION!M18 -> E26083
A19: 25304 | B19: 46044 | D19: DWUAM | E19: BASE DE MAQUILLAJE TONO 1 | F19: P | G19: 500 | H19: 35 | I19: =IF(OR(L19="entregado",K19="despacho",J19="en proceso"),"","ingreso") | J19: =IF(OR(L19="entregado",K19="despacho"),"", IF(AND(ELABORACION!F19<>"-",ELABORACION!F19<>"PENDIENTE ELAB"),"en proceso","")) | K19: =IF(L19="entregado","",IF(EXPEDICION!L19="listo para entregar","despacho","")) | L19: =IF(EXPEDICION!L19="entregado", "entregado", "") -> entregado | M19: =EXPEDICION!M19 -> E26104
A20: 26001 | B20: 46071 | C20: 6433 | D20: HEBURN | E20: BRUMA FIJADORA de MAQUILLAJE x 125 cc | F20: P | G20: 600 | H20: 125 | I20: =IF(OR(L20="entregado",K20="despacho",J20="en proceso"),"","ingreso") | J20: =IF(OR(L20="entregado",K20="despacho"),"", IF(AND(ELABORACION!F20<>"-",ELABORACION!F20<>"PENDIENTE ELAB"),"en proceso","")) | K20: =IF(L20="entregado","",IF(EXPEDICION!L20="listo para entregar","despacho","")) | L20: =IF(EXPEDICION!L20="entregado", "entregado", "") -> entregado | M20: =EXPEDICION!M20 -> M26003
A21: 26002 | B21: 46052 | D21: ALL BEAUTY | E21: CREMA FACIAL HIDRATANTE X 50gr (DIA) | F21: P | G21: 1000 | H21: 50 | I21: =IF(OR(L21="entregado",K21="despacho",J21="en proceso"),"","ingreso") | J21: =IF(OR(L21="entregado",K21="despacho"),"", IF(AND(ELABORACION!F21<>"-",ELABORACION!F21<>"PENDIENTE ELAB"),"en proceso","")) | K21: =IF(L21="entregado","",IF(EXPEDICION!L21="listo para entregar","despacho","")) | L21: =IF(EXPEDICION!L21="entregado", "entregado", "") -> entregado | M21: =EXPEDICION!M21 -> F26040
A22: 26002 | B22: 46052 | D22: ALL BEAUTY | E22: UNGÜENTO POMADA OLEO 30 + 1 X 10gr | F22: P | G22: 1000 | H22: 10 | I22: =IF(OR(L22="entregado",K22="despacho",J22="en proceso"),"","ingreso") | J22: =IF(OR(L22="entregado",K22="despacho"),"", IF(AND(ELABORACION!F22<>"-",ELABORACION!F22<>"PENDIENTE ELAB"),"en proceso","")) | K22: =IF(L22="entregado","",IF(EXPEDICION!L22="listo para entregar","despacho","")) | L22: =IF(EXPEDICION!L22="entregado", "entregado", "") -> entregado | M22: =EXPEDICION!M22 -> F26045
A23: 26002 | B23: 46052 | D23: ALL BEAUTY | E23: CREMA DE ORDEÑE X 300gr | F23: M | G23: 1500 | H23: 300 | I23: =IF(OR(L23="entregado",K23="despacho",J23="en proceso"),"","ingreso") | J23: =IF(OR(L23="entregado",K23="despacho"),"", IF(AND(ELABORACION!F23<>"-",ELABORACION!F23<>"PENDIENTE ELAB"),"en proceso","")) | K23: =IF(L23="entregado","",IF(EXPEDICION!L23="listo para entregar","despacho","")) | L23: =IF(EXPEDICION!L23="entregado", "entregado", "") -> entregado | M23: =EXPEDICION!M23 -> F26039
A24: 26003 | B24: 46043 | C24: 103 | D24: UNICA | E24: CREMA ENEBRO | F24: M | G24: 500 | H24: 90 | I24: =IF(OR(L24="entregado",K24="despacho",J24="en proceso"),"","ingreso") | J24: =IF(OR(L24="entregado",K24="despacho"),"", IF(AND(ELABORACION!F24<>"-",ELABORACION!F24<>"PENDIENTE ELAB"),"en proceso","")) | K24: =IF(L24="entregado","",IF(EXPEDICION!L24="listo para entregar","despacho","")) | L24: =IF(EXPEDICION!L24="entregado", "entregado", "") -> entregado | M24: =EXPEDICION!M24 -> 200301
A25: 26004 | B25: 46066 | C25: 15114 | D25: THELMA Y LOUISE | E25: SERUM BIFASICO JOJOBA-POMELO | F25: M | G25: 3024 | H25: 30 | I25: =IF(OR(L25="entregado",K25="despacho",J25="en proceso"),"","ingreso") | J25: =IF(OR(L25="entregado",K25="despacho"),"", IF(AND(ELABORACION!F25<>"-",ELABORACION!F25<>"PENDIENTE ELAB"),"en proceso","")) | K25: =IF(L25="entregado","",IF(EXPEDICION!L25="listo para entregar","despacho","")) | L25: =IF(EXPEDICION!L25="entregado", "entregado", "") -> entregado | M25: =EXPEDICION!M25 -> M26024
A26: 26004 | B26: 46066 | C26: 15114 | D26: THELMA Y LOUISE | E26: SERUM BIFASICO PEPINO-HAMAMELIS | F26: M | G26: 3024 | H26: 30 | I26: =IF(OR(L26="entregado",K26="despacho",J26="en proceso"),"","ingreso") | J26: =IF(OR(L26="entregado",K26="despacho"),"", IF(AND(ELABORACION!F26<>"-",ELABORACION!F26<>"PENDIENTE ELAB"),"en proceso","")) | K26: =IF(L26="entregado","",IF(EXPEDICION!L26="listo para entregar","despacho","")) | L26: =IF(EXPEDICION!L26="entregado", "entregado", "") -> entregado | M26: =EXPEDICION!M26 -> M26083
A27: 26004 | B27: 46066 | C27: 15114 | D27: THELMA Y LOUISE | E27: SERUM BIFASICO LAVANDA-BLUEBERRY | F27: M | G27: 3024 | H27: 30 | I27: =IF(OR(L27="entregado",K27="despacho",J27="en proceso"),"","ingreso") | J27: =IF(OR(L27="entregado",K27="despacho"),"", IF(AND(ELABORACION!F27<>"-",ELABORACION!F27<>"PENDIENTE ELAB"),"en proceso","")) | K27: =IF(L27="entregado","",IF(EXPEDICION!L27="listo para entregar","despacho","")) | L27: =IF(EXPEDICION!L27="entregado", "entregado", "") -> entregado | M27: =EXPEDICION!M27 -> M26022
A28: 26004 | B28: 46066 | C28: 15114 | D28: THELMA Y LOUISE | E28: SERUM BIFASICO ROSA MOSQUETA-ROSAS | F28: M | G28: 3024 | H28: 30 | I28: =IF(OR(L28="entregado",K28="despacho",J28="en proceso"),"","ingreso") | J28: =IF(OR(L28="entregado",K28="despacho"),"", IF(AND(ELABORACION!F28<>"-",ELABORACION!F28<>"PENDIENTE ELAB"),"en proceso","")) | K28: =IF(L28="entregado","",IF(EXPEDICION!L28="listo para entregar","despacho","")) | L28: =IF(EXPEDICION!L28="entregado", "entregado", "") -> entregado | M28: =EXPEDICION!M28 -> M26084
A29: 26005 | B29: 46071 | C29: 772 | D29: CAV | E29: SHAMPOO BIO MOLECULAR X400ML VITAMIN SHOCK | F29: M | G29: 700 | H29: 400 | I29: =IF(OR(L29="entregado",K29="despacho",J29="en proceso"),"","ingreso") | J29: =IF(OR(L29="entregado",K29="despacho"),"", IF(AND(ELABORACION!F29<>"-",ELABORACION!F29<>"PENDIENTE ELAB"),"en proceso","")) | K29: =IF(L29="entregado","",IF(EXPEDICION!L29="listo para entregar","despacho","")) | L29: =IF(EXPEDICION!L29="entregado", "entregado", "") -> entregado | M29: =EXPEDICION!M29 -> E26064
A30: 26005 | B30: 46071 | C30: 772 | D30: CAV | E30: SERUM BIO MOLUECULAR X30ML VITAMIN SHOCK | F30: P | G30: 300 | H30: 30 | I30: =IF(OR(L30="entregado",K30="despacho",J30="en proceso"),"","ingreso") | J30: =IF(OR(L30="entregado",K30="despacho"),"", IF(AND(ELABORACION!F30<>"-",ELABORACION!F30<>"PENDIENTE ELAB"),"en proceso","")) | K30: =IF(L30="entregado","",IF(EXPEDICION!L30="listo para entregar","despacho","")) | L30: =IF(EXPEDICION!L30="entregado", "entregado", "") -> entregado | M30: =EXPEDICION!M30 -> M26009
A31: 26005 | B31: 46071 | C31: 772 | D31: CAV | E31: BALSAMO X400ML BIOMIC C/ ACIDO HIAL + CAPIMAX | F31: M | G31: 400 | H31: 400 | I31: =IF(OR(L31="entregado",K31="despacho",J31="en proceso"),"","ingreso") | J31: =IF(OR(L31="entregado",K31="despacho"),"", IF(AND(ELABORACION!F31<>"-",ELABORACION!F31<>"PENDIENTE ELAB"),"en proceso","")) -> en proceso | K31: =IF(L31="entregado","",IF(EXPEDICION!L31="listo para entregar","despacho","")) | L31: =IF(EXPEDICION!L31="entregado", "entregado", "") | M31: =EXPEDICION!M31
A32: 26005 | B32: 46071 | C32: 772 | D32: CAV | E32: MASCARA BIO MOLECULAR VITAMIN SHOCK X300ML | F32: M | G32: 700 | H32: 300 | I32: =IF(OR(L32="entregado",K32="despacho",J32="en proceso"),"","ingreso") | J32: =IF(OR(L32="entregado",K32="despacho"),"", IF(AND(ELABORACION!F32<>"-",ELABORACION!F32<>"PENDIENTE ELAB"),"en proceso","")) | K32: =IF(L32="entregado","",IF(EXPEDICION!L32="listo para entregar","despacho","")) | L32: =IF(EXPEDICION!L32="entregado", "entregado", "") -> entregado | M32: =EXPEDICION!M32 -> M26045
A33: 26006 | B33: 46071 | C33: 14329 | D33: JACTANS - DISNEY | E33: DSH-41823-Shampoo infantil fco pvc x45ml | F33: M | G33: 3000 | H33: 45 | I33: =IF(OR(L33="entregado",K33="despacho",J33="en proceso"),"","ingreso") | J33: =IF(OR(L33="entregado",K33="despacho"),"", IF(AND(ELABORACION!F33<>"-",ELABORACION!F33<>"PENDIENTE ELAB"),"en proceso","")) | K33: =IF(L33="entregado","",IF(EXPEDICION!L33="listo para entregar","despacho","")) | L33: =IF(EXPEDICION!L33="entregado", "entregado", "") -> entregado | M33: =EXPEDICION!M33 -> M26002
A34: 26006 | B34: 46071 | C34: 14329 | D34: JACTANS - DISNEY | E34: DES-41823-Espuma de Baño infantil fco pvc x45ml | F34: M | G34: 3000 | H34: 45 | I34: =IF(OR(L34="entregado",K34="despacho",J34="en proceso"),"","ingreso") | J34: =IF(OR(L34="entregado",K34="despacho"),"", IF(AND(ELABORACION!F34<>"-",ELABORACION!F34<>"PENDIENTE ELAB"),"en proceso","")) | K34: =IF(L34="entregado","",IF(EXPEDICION!L34="listo para entregar","despacho","")) | L34: =IF(EXPEDICION!L34="entregado", "entregado", "") -> entregado | M34: =EXPEDICION!M34 -> M26001
A35: 26007 | B35: 46071 | D35: BL COSMETICS | E35: ALISADO EXPERT | F35: M | G35: 500 | H35: 300 | I35: =IF(OR(L35="entregado",K35="despacho",J35="en proceso"),"","ingreso") | J35: =IF(OR(L35="entregado",K35="despacho"),"", IF(AND(ELABORACION!F35<>"-",ELABORACION!F35<>"PENDIENTE ELAB"),"en proceso","")) | K35: =IF(L35="entregado","",IF(EXPEDICION!L35="listo para entregar","despacho","")) | L35: =IF(EXPEDICION!L35="entregado", "entregado", "") -> entregado | M35: =EXPEDICION!M35 -> M26007
A36: 26007 | B36: 46071 | D36: BL COSMETICS | E36: ALISADO EXPERT X1KG | F36: M | G36: 500 | H36: 1000 | I36: =IF(OR(L36="entregado",K36="despacho",J36="en proceso"),"","ingreso") | J36: =IF(OR(L36="entregado",K36="despacho"),"", IF(AND(ELABORACION!F36<>"-",ELABORACION!F36<>"PENDIENTE ELAB"),"en proceso","")) | K36: =IF(L36="entregado","",IF(EXPEDICION!L36="listo para entregar","despacho","")) | L36: =IF(EXPEDICION!L36="entregado", "entregado", "") -> entregado | M36: =EXPEDICION!M36 -> M26007
A37: 26007 | B37: 46071 | D37: BL COSMETICS | E37: ALISADO KERATIN | F37: M | G37: 1000 | H37: 300 | I37: =IF(OR(L37="entregado",K37="despacho",J37="en proceso"),"","ingreso") | J37: =IF(OR(L37="entregado",K37="despacho"),"", IF(AND(ELABORACION!F37<>"-",ELABORACION!F37<>"PENDIENTE ELAB"),"en proceso","")) | K37: =IF(L37="entregado","",IF(EXPEDICION!L37="listo para entregar","despacho","")) | L37: =IF(EXPEDICION!L37="entregado", "entregado", "") -> entregado | M37: =EXPEDICION!M37 -> M26008
A38: 26008 | B38: 46071 | C38: P00147 | D38: LURE | E38: GOLD MASK | F38: M | G38: 600 | H38: 100 | I38: =IF(OR(L38="entregado",K38="despacho",J38="en proceso"),"","ingreso") | J38: =IF(OR(L38="entregado",K38="despacho"),"", IF(AND(ELABORACION!F38<>"-",ELABORACION!F38<>"PENDIENTE ELAB"),"en proceso","")) | K38: =IF(L38="entregado","",IF(EXPEDICION!L38="listo para entregar","despacho","")) | L38: =IF(EXPEDICION!L38="entregado", "entregado", "") -> entregado | M38: =EXPEDICION!M38 -> F26025
A39: 26009 | B39: 46071 | C39: TCL 2025-02-28 | D39: THE CHEMIST LOOK | E39: MANCHAS 5ML - PIGMENT PROTOCOL | F39: P | G39: 1000 | H39: 5 | I39: =IF(OR(L39="entregado",K39="despacho",J39="en proceso"),"","ingreso") | J39: =IF(OR(L39="entregado",K39="despacho"),"", IF(AND(ELABORACION!F39<>"-",ELABORACION!F39<>"PENDIENTE ELAB"),"en proceso","")) | K39: =IF(L39="entregado","",IF(EXPEDICION!L39="listo para entregar","despacho","")) | L39: =IF(EXPEDICION!L39="entregado", "entregado", "") -> entregado | M39: =EXPEDICION!M39 -> M26015
A40: 26009 | B40: 46071 | C40: TCL 2025-02-28 | D40: THE CHEMIST LOOK | E40: MANCHAS 30ML - PIGMENT PROTOCOL | F40: P | G40: 2000 | H40: 30 | I40: =IF(OR(L40="entregado",K40="despacho",J40="en proceso"),"","ingreso") | J40: =IF(OR(L40="entregado",K40="despacho"),"", IF(AND(ELABORACION!F40<>"-",ELABORACION!F40<>"PENDIENTE ELAB"),"en proceso","")) | K40: =IF(L40="entregado","",IF(EXPEDICION!L40="listo para entregar","despacho","")) | L40: =IF(EXPEDICION!L40="entregado", "entregado", "") -> entregado | M40: =EXPEDICION!M40 -> M26015
...

Sheet ELABORACION
A1: Fecha | B1: N° OC | C1: CLIENTE | D1: PRODUCTO | E1: KG | F1: ESTADO | G1: Graneles | H1: RESPONSABLE | I1: FECHA | J1: N°LOTE | K1: OBSERVACIONES
A2: =PEDIDOS!B2 -> 46035 | B2: =PEDIDOS!C2 -> 163 | C2: =PEDIDOS!D2 -> THE MINIMAL CO | D2: =PEDIDOS!E2 -> MILKY TONER | E2: =PEDIDOS!G2*PEDIDOS!H2/1000 -> 90 | F2: APROBADO | H2: NICOLAS | I2: =EXPEDICION!K2-7 -> 46069 | J2: =PEDIDOS!M2 -> F26021
A3: =PEDIDOS!B3 -> 46035 | B3: =PEDIDOS!C3 -> 14297 | C3: =PEDIDOS!D3 -> JACTANS | D3: =PEDIDOS!E3 -> JS-941 AGUA MICELAR BIFASCIA | E3: =PEDIDOS!G3*PEDIDOS!H3/1000 -> 105 | F3: APROBADO | H3: Nicolas | I3: =EXPEDICION!K3-7 -> 46073 | J3: =PEDIDOS!M3 -> F26031
A4: =PEDIDOS!B4 -> 46035 | B4: =PEDIDOS!C4 -> 15074 | C4: =PEDIDOS!D4 -> THELMA Y LOUISE | D4: =PEDIDOS!E4 -> AGUA TERMAL | E4: =PEDIDOS!G4*PEDIDOS!H4/1000 -> 294 | F4: APROBADO | H4: Cristian | I4: =EXPEDICION!K4-7 -> 46076 | J4: =PEDIDOS!M4 -> F26041
A5: =PEDIDOS!B5 -> 46035 | B5: =PEDIDOS!C5 | C5: =PEDIDOS!D5 -> LIORA | D5: =PEDIDOS!E5 -> CREMA PARA PEINAR RULOS | E5: =PEDIDOS!G5*PEDIDOS!H5/1000 -> 51 | F5: APROBADO | H5: Cristian | I5: =EXPEDICION!K5-7 -> 46154 | J5: =PEDIDOS!M5 -> Y26039 | K5: Falta fragancia
A6: =PEDIDOS!B6 -> 46042 | B6: =PEDIDOS!C6 -> P01203 | C6: =PEDIDOS!D6 -> BIOESENCIA | D6: =PEDIDOS!E6 -> SERUM ORIGENES | E6: =PEDIDOS!G6*PEDIDOS!H6/1000 -> 48 | F6: APROBADO | H6: Nicolás | I6: =EXPEDICION!K6-7 -> 46070 | J6: =PEDIDOS!M6 -> 240201
A7: =PEDIDOS!B7 -> 46042 | B7: =PEDIDOS!C7 | C7: =PEDIDOS!D7 -> WSABI | D7: =PEDIDOS!E7 -> SERUM INTIMO | E7: =PEDIDOS!G7*PEDIDOS!H7/1000 -> 9 | F7: APROBADO | H7: Santino | I7: =EXPEDICION!K7-7 -> 46080 | J7: =PEDIDOS!M7 -> F26049
A8: =PEDIDOS!B8 -> 46042 | B8: =PEDIDOS!C8 | C8: =PEDIDOS!D8 -> MERMER | D8: =PEDIDOS!E8 -> ACEITE CORPORAL LAVANDA | E8: =PEDIDOS!G8*PEDIDOS!H8/1000 -> 60 | F8: APROBADO | H8: NICOLAS | I8: =EXPEDICION!K8-7 -> 46043 | J8: =PEDIDOS!M8 -> E26087
A9: =PEDIDOS!B9 -> 46042 | B9: =PEDIDOS!C9 | C9: =PEDIDOS!D9 -> MERMER | D9: =PEDIDOS!E9 -> ACEITE CORPORAL ALMENDRA | E9: =PEDIDOS!G9*PEDIDOS!H9/1000 -> 60 | F9: APROBADO | H9: NICOLAS | I9: =EXPEDICION!K9-7 -> 46043 | J9: =PEDIDOS!M9 -> E26088
A10: =PEDIDOS!B10 -> 46042 | B10: =PEDIDOS!C10 | C10: =PEDIDOS!D10 -> MERMER | D10: =PEDIDOS!E10 -> ACEITE CORPORAL ROSAS | E10: =PEDIDOS!G10*PEDIDOS!H10/1000 -> 60 | F10: APROBADO | H10: CRISTIAN | I10: =EXPEDICION!K10-7 -> 46043 | J10: =PEDIDOS!M10 -> E26089
A11: =PEDIDOS!B11 -> 46042 | B11: =PEDIDOS!C11 | C11: =PEDIDOS!D11 -> MERMER | D11: =PEDIDOS!E11 -> ACEITE CORPORAL SESAMO | E11: =PEDIDOS!G11*PEDIDOS!H11/1000 -> 60 | F11: APROBADO | H11: CRISTIAN | I11: =EXPEDICION!K11-7 -> 46043 | J11: =PEDIDOS!M11 -> E26090
A12: =PEDIDOS!B12 -> 46042 | B12: =PEDIDOS!C12 | C12: =PEDIDOS!D12 -> MERMER | D12: =PEDIDOS!E12 -> ACEITE CORPORAL INCIENSO | E12: =PEDIDOS!G12*PEDIDOS!H12/1000 -> 60 | F12: APROBADO | H12: CRISTIAN | I12: =EXPEDICION!K12-7 -> 46043 | J12: =PEDIDOS!M12 -> E26091
A13: =PEDIDOS!B13 -> 46042 | B13: =PEDIDOS!C13 | C13: =PEDIDOS!D13 -> MERMER | D13: =PEDIDOS!E13 -> ACEITE CORPORAL ARNICA | E13: =PEDIDOS!G13*PEDIDOS!H13/1000 -> 60 | F13: APROBADO | H13: NICOLAS | I13: =EXPEDICION!K13-7 -> 46043 | J13: =PEDIDOS!M13 -> E26092
A14: =PEDIDOS!B14 -> 46042 | B14: =PEDIDOS!C14 | C14: =PEDIDOS!D14 -> MERMER | D14: =PEDIDOS!E14 -> LOCION CAPILAR | E14: =PEDIDOS!G14*PEDIDOS!H14/1000 -> 40 | F14: APROBADO | H14: Nicolás | I14: =EXPEDICION!K14-7 -> 46104 | J14: =PEDIDOS!M14 -> M26042
A15: =PEDIDOS!B15 -> 46042 | B15: =PEDIDOS!C15 | C15: =PEDIDOS!D15 -> MERMER | D15: =PEDIDOS!E15 -> SERUM CAPILAR | E15: =PEDIDOS!G15*PEDIDOS!H15/1000 -> 40 | F15: APROBADO | H15: Santino | I15: =EXPEDICION!K15-7 -> 46105 | J15: =PEDIDOS!M15 -> M26030
A16: =PEDIDOS!B16 -> 46049 | B16: =PEDIDOS!C16 -> 1708 | C16: =PEDIDOS!D16 -> LABORATORIO ONCE | D16: =PEDIDOS!E16 -> SERUM ACIDO HIALURONICO + NIACINAMIDA | E16: =PEDIDOS!G16*PEDIDOS!H16/1000 -> 49.59 | F16: APROBADO | H16: Cristian | I16: =EXPEDICION!K16-7 -> 46076 | J16: =PEDIDOS!M16 -> F26048
A17: =PEDIDOS!B17 -> 46050 | B17: =PEDIDOS!C17 -> 15098 | C17: =PEDIDOS!D17 -> THELMA Y LOUISE | D17: =PEDIDOS!E17 -> CREMA BIFASICA CHERRY | E17: =PEDIDOS!G17*PEDIDOS!H17/1000 -> 262.4 | F17: APROBADO | H17: Cristian | I17: =EXPEDICION!K17-7 -> -7 | J17: =PEDIDOS!M17
... A24: =PEDIDOS!B24 -> 46043 | B24: =PEDIDOS!C24 -> 103 | C24: =PEDIDOS!D24 -> UNICA | D24: =PEDIDOS!E24 -> CREMA ENEBRO | E24: =PEDIDOS!G24*PEDIDOS!H24/1000 -> 45 | F24: APROBADO | H24: Nicolás | I24: =EXPEDICION!K24-7 -> 46094 | J24: =PEDIDOS!M24 -> 200301
A25: =PEDIDOS!B25 -> 46066 | B25: =PEDIDOS!C25 -> 15114 | C25: =PEDIDOS!D25 -> THELMA Y LOUISE | D25: =PEDIDOS!E25 -> SERUM BIFASICO JOJOBA-POMELO | E25: =PEDIDOS!G25*PEDIDOS!H25/1000 -> 90.72 | F25: APROBADO | H25: Valentin | I25: 46087 | J25: =PEDIDOS!M25 -> M26024
A26: =PEDIDOS!B26 -> 46066 | B26: =PEDIDOS!C26 -> 15114 | C26: =PEDIDOS!D26 -> THELMA Y LOUISE | D26: =PEDIDOS!E26 -> SERUM BIFASICO PEPINO-HAMAMELIS | E26: =PEDIDOS!G26*PEDIDOS!H26/1000 -> 90.72 | F26: APROBADO | H26: Nicolás | I26: =EXPEDICION!K26-7 -> 46100 | J26: =PEDIDOS!M26 -> M26083
A27: =PEDIDOS!B27 -> 46066 | B27: =PEDIDOS!C27 -> 15114 | C27: =PEDIDOS!D27 -> THELMA Y LOUISE | D27: =PEDIDOS!E27 -> SERUM BIFASICO LAVANDA-BLUEBERRY | E27: =PEDIDOS!G27*PEDIDOS!H27/1000 -> 90.72 | F27: APROBADO | H27: Cristián | I27: =EXPEDICION!K27-7 -> 46086 | J27: =PEDIDOS!M27 -> M26022
A28: =PEDIDOS!B28 -> 46066 | B28: =PEDIDOS!C28 -> 15114 | C28: =PEDIDOS!D28 -> THELMA Y LOUISE | D28: =PEDIDOS!E28 -> SERUM BIFASICO ROSA MOSQUETA-ROSAS | E28: =PEDIDOS!G28*PEDIDOS!H28/1000 -> 90.72 | F28: APROBADO | H28: Nicolas | I28: =EXPEDICION!K28-7 -> 46101 | J28: =PEDIDOS!M28 -> M26084
A29: =PEDIDOS!B29 -> 46071 | B29: =PEDIDOS!C29 -> 772 | C29: =PEDIDOS!D29 -> CAV | D29: =PEDIDOS!E29 -> SHAMPOO BIO MOLECULAR X400ML VITAMIN SHOCK | E29: =PEDIDOS!G29*PEDIDOS!H29/1000 -> 280 | F29: APROBADO | H29: Cristian | I29: =EXPEDICION!K29-7 -> 46080 | J29: =PEDIDOS!M29 -> E26064
A30: =PEDIDOS!B30 -> 46071 | B30: =PEDIDOS!C30 -> 772 | C30: =PEDIDOS!D30 -> CAV | D30: =PEDIDOS!E30 -> SERUM BIO MOLUECULAR X30ML VITAMIN SHOCK | E30: =PEDIDOS!G30*PEDIDOS!H30/1000 -> 9 | F30: APROBADO | H30: Nicolás | I30: =EXPEDICION!K30-7 -> 46087 | J30: =PEDIDOS!M30 -> M26009
A31: =PEDIDOS!B31 -> 46071 | B31: =PEDIDOS!C31 -> 772 | C31: =PEDIDOS!D31 -> CAV | D31: =PEDIDOS!E31 -> BALSAMO X400ML BIOMIC C/ ACIDO HIAL + CAPIMAX | E31: =PEDIDOS!G31*PEDIDOS!H31/1000 -> 160 | F31: APROBADO | H31: Cristian | I31: =EXPEDICION!K31-7 -> -7 | J31: =PEDIDOS!M31
A32: =PEDIDOS!B32 -> 46071 | B32: =PEDIDOS!C32 -> 772 | C32: =PEDIDOS!D32 -> CAV | D32: =PEDIDOS!E32 -> MASCARA BIO MOLECULAR VITAMIN SHOCK X300ML | E32: =PEDIDOS!G32*PEDIDOS!H32/1000 -> 210 | F32: APROBADO | H32: Cristian | I32: =EXPEDICION!K32-7 -> 46090 | J32: =PEDIDOS!M32 -> M26045
A33: =PEDIDOS!B33 -> 46071 | B33: =PEDIDOS!C33 -> 14329 | C33: =PEDIDOS!D33 -> JACTANS - DISNEY | D33: =PEDIDOS!E33 -> DSH-41823-Shampoo infantil fco pvc x45ml | E33: =PEDIDOS!G33*PEDIDOS!H33/1000 -> 135 | F33: APROBADO | H33: Santino | I33: =EXPEDICION!K33-7 -> 46079 | J33: =PEDIDOS!M33 -> M26002
A34: =PEDIDOS!B34 -> 46071 | B34: =PEDIDOS!C34 -> 14329 | C34: =PEDIDOS!D34 -> JACTANS - DISNEY | D34: =PEDIDOS!E34 -> DES-41823-Espuma de Baño infantil fco pvc x45ml | E34: =PEDIDOS!G34*PEDIDOS!H34/1000 -> 135 | F34: APROBADO | H34: Santino | I34: =EXPEDICION!K34-7 -> 46078 | J34: =PEDIDOS!M34 -> M26001
A35: =PEDIDOS!B35 -> 46071 | B35: =PEDIDOS!C35 | C35: =PEDIDOS!D35 -> BL COSMETICS | D35: =PEDIDOS!E35 -> ALISADO EXPERT | E35: =PEDIDOS!G35*PEDIDOS!H35/1000 -> 150 | F35: APROBADO | H35: Cristian | I35: =EXPEDICION!K35-7 -> 46078 | J35: =PEDIDOS!M35 -> M26007
A36: =PEDIDOS!B36 -> 46071 | B36: =PEDIDOS!C36 | C36: =PEDIDOS!D36 -> BL COSMETICS | D36: =PEDIDOS!E36 -> ALISADO EXPERT X1KG | E36: =PEDIDOS!G36*PEDIDOS!H36/1000 -> 500 | F36: APROBADO | H36: Cristian | I36: =EXPEDICION!K36-7 -> 46080 | J36: =PEDIDOS!M36 -> M26007
A37: =PEDIDOS!B37 -> 46071 | B37: =PEDIDOS!C37 | C37: =PEDIDOS!D37 -> BL COSMETICS | D37: =PEDIDOS!E37 -> ALISADO KERATIN | E37: =PEDIDOS!G37*PEDIDOS!H37/1000 -> 300 | F37: APROBADO | H37: Cristian | I37: =EXPEDICION!K37-7 -> 46083 | J37: =PEDIDOS!M37 -> M26008
... A44: =PEDIDOS!B44 -> 46071 | B44: =PEDIDOS!C44 -> TCL 2025-02-28 | C44: =PEDIDOS!D44 -> THE CHEMIST LOOK | D44: =PEDIDOS!E44 -> BOOSTER MUNAP-18 | E44: =PEDIDOS!G44*PEDIDOS!H44/1000 -> 45 | F44: APROBADO | H44: cristian | I44: =EXPEDICION!K44-7 -> 46161 | J44: =PEDIDOS!M44 -> Y26017
A45: =PEDIDOS!B45 -> 46071 | B45: =PEDIDOS!C45 -> TCL 2025-02-28 | C45: =PEDIDOS!D45 -> THE CHEMIST LOOK | D45: =PEDIDOS!E45 -> TAN BOOSTER | E45: =PEDIDOS!G45*PEDIDOS!H45/1000 -> 15 | F45: - | I45: =EXPEDICION!K45-7 -> -7 | J45: =PEDIDOS!M45
A46: =PEDIDOS!B46 -> 46071 | B46: =PEDIDOS!C46 -> TCL 2025-02-28 | C46: =PEDIDOS!D46 -> THE CHEMIST LOOK | D46: =PEDIDOS!E46 -> BOOSTER RETIN | E46: =PEDIDOS!G46*PEDIDOS!H46/1000 -> 30 | F46: APROBADO | H46: nicolas | I46: =EXPEDICION!K46-7 -> 46135 | J46: =PEDIDOS!M46 -> A26018
A47: =PEDIDOS!B47 -> 46071 | B47: =PEDIDOS!C47 -> TCL 2025-02-28 | C47: =PEDIDOS!D47 -> THE CHEMIST LOOK | D47: =PEDIDOS!E47 -> 2ND SKIN | E47: =PEDIDOS!G47*PEDIDOS!H47/1000 -> 50 | F47: - | I47: =EXPEDICION!K47-7 -> -7 | J47: =PEDIDOS!M47
A48: =PEDIDOS!B48 -> 46071 | B48: =PEDIDOS!C48 -> 14331 | C48: =PEDIDOS!D48 -> JACTANS | D48: =PEDIDOS!E48 -> JS-736 BRUMA FIJADORA FACIAL | E48: =PEDIDOS!G48*PEDIDOS!H48/1000 -> 60 | F48: APROBADO | I48: =EXPEDICION!K48-7 -> 46157 | J48: =PEDIDOS!M48 -> Y26022
A49: =PEDIDOS!B49 -> 46072 | B49: =PEDIDOS!C49 | C49: =PEDIDOS!D49 -> KALA | D49: =PEDIDOS!E49 -> AGUA DE ROSAS | E49: =PEDIDOS!G49*PEDIDOS!H49/1000 -> 58.5 | F49: APROBADO | H49: Nicolás | I49: =EXPEDICION!K49-7 -> 46079 | J49: =PEDIDOS!M49 -> F26057
A50: =PEDIDOS!B50 -> 46073 | B50: =PEDIDOS!C50 | C50: =PEDIDOS!D50 -> INTENCIONAL | D50: =PEDIDOS!E50 -> CREMA DE ORDEÑE | E50: =PEDIDOS!G50*PEDIDOS!H50/1000 -> 500 | F50: APROBADO | H50: Nicolas | I50: =EXPEDICION!K50-7 -> 46087 | J50: =PEDIDOS!M50 -> F26062
A51: =PEDIDOS!B51 -> 46073 | B51: =PEDIDOS!C51 -> P01256 | C51: =PEDIDOS!D51 -> BIOESENCIA | D51: =PEDIDOS!E51 -> CREMA BABA DE CARACOL | E51: =PEDIDOS!G51*PEDIDOS!H51/1000 -> 50 | F51: APROBADO | H51: Nicolas | I51: =EXPEDICION!K51-7 -> 46076 | J51: =PEDIDOS!M51 -> 270201
A52: =PEDIDOS!B52 -> 46042 | B52: =PEDIDOS!C52 -> P01203 | C52: =PEDIDOS!D52 -> BIOESENCIA | D52: =PEDIDOS!E52 -> SHAMPOO BABY | E52: =PEDIDOS!G52*PEDIDOS!H52/1000 -> 125 | F52: APROBADO | H52: Cristian | I52: =EXPEDICION!K52-7 -> 46066 | J52: =PEDIDOS!M52 -> F26023
...

Sheet EXPEDICION
A1: Nº | B1: Fecha | C1: N° OC | D1: CLIENTE | E1: PRODUCTO | F1: Q PEDIDA | G1: Q envasada | H1: S | I1: Nv Svcio | J1: CANTIDAD CAJAS | K1: FECHA | L1: ESTADO | M1: N° DE LOTE | N1: N° REMITO | O1: OBSERVACIÓN
A2: =PEDIDOS!A2 -> 25293 | B2: =PEDIDOS!B2 -> 46035 | C2: =PEDIDOS!C2 -> 163 | D2: =PEDIDOS!D2 -> THE MINIMAL CO | E2: =PEDIDOS!E2 -> MILKY TONER | F2: =PEDIDOS!G2 -> 900 | G2: =25*35+24 -> 899 | H2: =PEDIDOS!F2 -> P | I2: =IF(G2<>"",-(F2-G2)/F2+1, "") -> 0.99888889 | J2: 25 x 35u + 1 x 24u | K2: 46076 | L2: =IF(N2<>"","ENTREGADO",IF(K2<>"","LISTO PARA ENTREGAR","EN PROCESO" )) -> ENTREGADO | M2: F26021 | N2: 3351
A3: =PEDIDOS!A3 -> 25294 | B3: =PEDIDOS!B3 -> 46035 | C3: =PEDIDOS!C3 -> 14297 | D3: =PEDIDOS!D3 -> JACTANS | E3: =PEDIDOS!E3 -> JS-941 AGUA MICELAR BIFASCIA | F3: =PEDIDOS!G3 -> 1000 | G3: 1011 | H3: =PEDIDOS!F3 -> P | I3: =IF(G3<>"",-(F3-G3)/F3+1, "") -> 1.011 | J3: 50X20 1X11 | K3: 46080 | L3: =IF(N3<>"","ENTREGADO",IF(K3<>"","LISTO PARA ENTREGAR","EN PROCESO" )) -> ENTREGADO | M3: F26031 | N3: 3376
A4: =PEDIDOS!A4 -> 25295 | B4: =PEDIDOS!B4 -> 46035 | C4: =PEDIDOS!C4 -> 15074 | D4: =PEDIDOS!D4 -> THELMA Y LOUISE | E4: =PEDIDOS!E4 -> AGUA TERMAL | F4: =PEDIDOS!G4 -> 2940 | G4: 2912 | H4: =PEDIDOS!F4 -> P | I4: =IF(G4<>"",-(F4-G4)/F4+1, "") -> 0.99047619 | J4: 64x45 1x32 | K4: 46083 | L4: =IF(N4<>"","ENTREGADO",IF(K4<>"","LISTO PARA ENTREGAR","EN PROCESO" )) -> ENTREGADO | M4: F26041 | N4: 3368
A5: =PEDIDOS!A5 -> 25296 | B5: =PEDIDOS!B5 -> 46035 | C5: =PEDIDOS!C5 | D5: =PEDIDOS!D5 -> LIORA | E5: =PEDIDOS!E5 -> CREMA PARA PEINAR RULOS | F5: =PEDIDOS!G5 -> 170 | G5: 147 | H5: =PEDIDOS!F5 -> P | I5: =IF(G5<>"",-(F5-G5)/F5+1, "") -> 0.86470588 | J5: 7X21U | K5: 46161 | L5: =IF(N5<>"","ENTREGADO",IF(K5<>"","LISTO PARA ENTREGAR","EN PROCESO" )) -> ENTREGADO | M5: Y26039 | N5: 3496
A6: =PEDIDOS!A6 -> 25298 | B6: =PEDIDOS!B6 -> 46042 | C6: =PEDIDOS!C6 -> P01203 | D6: =PEDIDOS!D6 -> BIOESENCIA | E6: =PEDIDOS!E6 -> SERUM ORIGENES | F6: =PEDIDOS!G6 -> 1600 | G6: =6*220+79+203 -> 1602 | H6: =PEDIDOS!F6 -> P | I6: =IF(G6<>"",-(F6-G6)/F6+1, "") -> 1.00125 | J6: 6 x 220u + 1 x 79 / 1 x 203u | K6: 46077 | L6: =IF(N6<>"","ENTREGADO",IF(K6<>"","LISTO PARA ENTREGAR","EN PROCESO" )) -> ENTREGADO | M6: 240201 | N6: 240226 /310326
A7: =PEDIDOS!A7 -> 25299 | B7: =PEDIDOS!B7 -> 46042 | C7: =PEDIDOS!C7 | D7: =PEDIDOS!D7 -> WSABI | E7: =PEDIDOS!E7 -> SERUM INTIMO | F7: =PEDIDOS!G7 -> 300 | G7: 293 | H7: =PEDIDOS!F7 -> P | I7: =IF(G7<>"",-(F7-G7)/F7+1, "") -> 0.97666667 | J7: 8X34 1X21 | K7: 46087 | L7: =IF(N7<>"","ENTREGADO",IF(K7<>"","LISTO PARA ENTREGAR","EN PROCESO" )) -> ENTREGADO | M7: F26049 | N7: 3371
A8: =PEDIDOS!A8 -> 25300 | B8: =PEDIDOS!B8 -> 46042 | C8: =PEDIDOS!C8 | D8: =PEDIDOS!D8 -> MERMER | E8: =PEDIDOS!E8 -> ACEITE CORPORAL LAVANDA | F8: =PEDIDOS!G8 -> 300 | G8: 509 | H8: =PEDIDOS!F8 -> P | I8: =IF(G8<>"",-(F8-G8)/F8+1, "") -> 1.6966667 | J8: 16 x 30u + 1 x 29u | K8: 46050 | L8: =IF(N8<>"","ENTREGADO",IF(K8<>"","LISTO PARA ENTREGAR","EN PROCESO" )) -> ENTREGADO | M8: E26087 | N8: 2997
A9: =PEDIDOS!A9 -> 25300 | B9: =PEDIDOS!B9 -> 46042 | C9: =PEDIDOS!C9 | D9: =PEDIDOS!D9 -> MERMER | E9: =PEDIDOS!E9 -> ACEITE CORPORAL ALMENDRA | F9: =PEDIDOS!G9 -> 300 | G9: 306 | H9: =PEDIDOS!F9 -> P | I9: =IF(G9<>"",-(F9-G9)/F9+1, "") -> 1.02 | J9: 17X18 | K9: 46050 | L9: =IF(N9<>"","ENTREGADO",IF(K9<>"","LISTO PARA ENTREGAR","EN PROCESO" )) -> ENTREGADO | M9: E26088 | N9: 2997
A10: =PEDIDOS!A10 -> 25300 | B10: =PEDIDOS!B10 -> 46042 | C10: =PEDIDOS!C10 | D10: =PEDIDOS!D10 -> MERMER | E10: =PEDIDOS!E10 -> ACEITE CORPORAL ROSAS | F10: =PEDIDOS!G10 -> 300 | G10: 303 | H10: =PEDIDOS!F10 -> P | I10: =IF(G10<>"",-(F10-G10)/F10+1, "") -> 1.01 | J10: 16X18 1X15 | K10: 46050 | L10: =IF(N10<>"","ENTREGADO",IF(K10<>"","LISTO PARA ENTREGAR","EN PROCESO" )) -> ENTREGADO | M10: E26089 | N10: 2997
A11: =PEDIDOS!A11 -> 25300 | B11: =PEDIDOS!B11 -> 46042 | C11: =PEDIDOS!C11 | D11: =PEDIDOS!D11 -> MERMER | E11: =PEDIDOS!E11 -> ACEITE CORPORAL SESAMO | F11: =PEDIDOS!G11 -> 300 | G11: 312 | H11: =PEDIDOS!F11 -> P | I11: =IF(G11<>"",-(F11-G11)/F11+1, "") -> 1.04 | J11: 17X18 1X6 | K11: 46050 | L11: =IF(N11<>"","ENTREGADO",IF(K11<>"","LISTO PARA ENTREGAR","EN PROCESO" )) -> ENTREGADO | M11: E26090 | N11: 2997
A12: =PEDIDOS!A12 -> 25300 | B12: =PEDIDOS!B12 -> 46042 | C12: =PEDIDOS!C12 | D12: =PEDIDOS!D12 -> MERMER | E12: =PEDIDOS!E12 -> ACEITE CORPORAL INCIENSO | F12: =PEDIDOS!G12 -> 300 | G12: 306 | H12: =PEDIDOS!F12 -> P | I12: =IF(G12<>"",-(F12-G12)/F12+1, "") -> 1.02 | J12: 17X18 | K12: 46050 | L12: =IF(N12<>"","ENTREGADO",IF(K12<>"","LISTO PARA ENTREGAR","EN PROCESO" )) -> ENTREGADO | M12: E26091 | N12: 2997
A13: =PEDIDOS!A13 -> 25300 | B13: =PEDIDOS!B13 -> 46042 | C13: =PEDIDOS!C13 | D13: =PEDIDOS!D13 -> MERMER | E13: =PEDIDOS!E13 -> ACEITE CORPORAL ARNICA | F13: =PEDIDOS!G13 -> 300 | G13: 304 | H13: =PEDIDOS!F13 -> P | I13: =IF(G13<>"",-(F13-G13)/F13+1, "") -> 1.0133333 | J13: 16X18 1X16 | K13: 46050 | L13: =IF(N13<>"","ENTREGADO",IF(K13<>"","LISTO PARA ENTREGAR","EN PROCESO" )) -> ENTREGADO | M13: E26092 | N13: 2997
A14: =PEDIDOS!A14 -> 25300 | B14: =PEDIDOS!B14 -> 46042 | C14: =PEDIDOS!C14 | D14: =PEDIDOS!D14 -> MERMER | E14: =PEDIDOS!E14 -> LOCION CAPILAR | F14: =PEDIDOS!G14 -> 400 | G14: =8*46+32 -> 400 | H14: =PEDIDOS!F14 -> P | I14: =IF(G14<>"",-(F14-G14)/F14+1, "") -> 1 | J14: 8 x 46 + 1 x 32 | K14: 46111 | L14: =IF(N14<>"","ENTREGADO",IF(K14<>"","LISTO PARA ENTREGAR","EN PROCESO" )) -> ENTREGADO | M14: M26042 | N14: 4312
A15: =PEDIDOS!A15 -> 25300 | B15: =PEDIDOS!B15 -> 46042 | C15: =PEDIDOS!C15 | D15: =PEDIDOS!D15 -> MERMER | E15: =PEDIDOS!E15 -> SERUM CAPILAR | F15: =PEDIDOS!G15 -> 400 | G15: =9*45+10 -> 415 | H15: =PEDIDOS!F15 -> P | I15: =IF(G15<>"",-(F15-G15)/F15+1, "") -> 1.0375 | J15: 9 x 45 + 1 x 10 | K15: 46112 | L15: =IF(N15<>"","ENTREGADO",IF(K15<>"","LISTO PARA ENTREGAR","EN PROCESO" )) -> ENTREGADO | M15: M26030 | N15: 3412
A16: =PEDIDOS!A16 -> 25301 | B16: =PEDIDOS!B16 -> 46049 | C16: =PEDIDOS!C16 -> 1708 | D16: =PEDIDOS!D16 -> LABORATORIO ONCE | E16: =PEDIDOS!E16 -> SERUM ACIDO HIALURONICO + NIACINAMIDA | F16: =PEDIDOS!G16 -> 1653 | G16: 1549 | H16: =PEDIDOS!F16 -> P | I16: =IF(G16<>"",-(F16-G16)/F16+1, "") -> 0.93708409 | J16: 17X90U Y 1X19U | K16: 46083 | L16: =IF(N16<>"","ENTREGADO",IF(K16<>"","LISTO PARA ENTREGAR","EN PROCESO" )) -> ENTREGADO | M16: F26048 | N16: 3362
A17: =PEDIDOS!A17 -> 25302 | B17: =PEDIDOS!B17 -> 46050 | C17: =PEDIDOS!C17 -> 15098 | D17: =PEDIDOS!D17 -> THELMA Y LOUISE | E17: =PEDIDOS!E17 -> CREMA BIFASICA CHERRY | F17: =PEDIDOS!G17 -> 1640 | G17: =37*37+22 -> 1391 | H17: =PEDIDOS!F17 -> M | I17: =IF(G17<>"",-(F17-G17)/F17+1, "") -> 0.84817073 | J17: 37X37 1X22 | L17: =IF(N17<>"","ENTREGADO",IF(K17<>"","LISTO PARA ENTREGAR","EN PROCESO" )) -> ENTREGADO | N17: 7
A18: =PEDIDOS!A18 -> 25303 | B18: =PEDIDOS!B18 -> 46052 | C18: =PEDIDOS!C18 | D18: =PEDIDOS!D18 -> ALL BEAUTY | E18: =PEDIDOS!E18 -> SERUM ACIDO HIALURONICO | F18: =PEDIDOS!G18 -> 1000 | G18: =13*70+15 -> 925 | H18: =PEDIDOS!F18 -> P | I18: =IF(G18<>"",-(F18-G18)/F18+1, "") -> 0.925 | J18: 13 x 70u + 1 x 15u | K18: 46077 | L18: =IF(N18<>"","ENTREGADO",IF(K18<>"","LISTO PARA ENTREGAR","EN PROCESO" )) -> ENTREGADO | M18: E26083 | N18: 3353
A19: =PEDIDOS!A19 -> 25304 | B19: =PEDIDOS!B19 -> 46044 | C19: =PEDIDOS!C19 | D19: =PEDIDOS!D19 -> DWUAM | E19: =PEDIDOS!E19 -> BASE DE MAQUILLAJE TONO 1 | F19: =PEDIDOS!G19 -> 500 | G19: 419 | H19: =PEDIDOS!F19 -> P | I19: =IF(G19<>"",-(F19-G19)/F19+1, "") -> 0.838 | K19: 46051 | L19: =IF(N19<>"","ENTREGADO",IF(K19<>"","LISTO PARA ENTREGAR","EN PROCESO" )) -> ENTREGADO | M19: E26104 | N19: 3001
A20: =PEDIDOS!A20 -> 26001 | B20: =PEDIDOS!B20 -> 46071 | C20: =PEDIDOS!C20 -> 6433 | D20: =PEDIDOS!D20 -> HEBURN | E20: =PEDIDOS!E20 -> BRUMA FIJADORA de MAQUILLAJE x 125 cc | F20: =PEDIDOS!G20 -> 600 | G20: 490 | H20: =PEDIDOS!F20 -> P | I20: =IF(G20<>"",-(F20-G20)/F20+1, "") -> 0.81666667 | J20: 8x42 1x28/ 3x42 | K20: 46086 | L20: =IF(N20<>"","ENTREGADO",IF(K20<>"","LISTO PARA ENTREGAR","EN PROCESO" )) -> ENTREGADO | M20: M26003 | N20: 3396
A21: =PEDIDOS!A21 -> 26002 | B21: =PEDIDOS!B21 -> 46052 | C21: =PEDIDOS!C21 | D21: =PEDIDOS!D21 -> ALL BEAUTY | E21: =PEDIDOS!E21 -> CREMA FACIAL HIDRATANTE X 50gr (DIA) | F21: =PEDIDOS!G21 -> 1000 | G21: =34*24+15+60+42 -> 933 | H21: =PEDIDOS!F21 -> P | I21: =IF(G21<>"",-(F21-G21)/F21+1, "") -> 0.933 | J21: 36 x 24 + 1 x 15u + 1 x 60u + 1 x 42u | K21: 46079 | L21: =IF(N21<>"","ENTREGADO",IF(K21<>"","LISTO PARA ENTREGAR","EN PROCESO" )) -> ENTREGADO | M21: F26040 | N21: 3353
A22: =PEDIDOS!A22 -> 26002 | B22: =PEDIDOS!B22 -> 46052 | C22: =PEDIDOS!C22 | D22: =PEDIDOS!D22 -> ALL BEAUTY | E22: =PEDIDOS!E22 -> UNGÜENTO POMADA OLEO 30 + 1 X 10gr | F22: =PEDIDOS!G22 -> 1000 | G22: =374*2+233 -> 981 | H22: =PEDIDOS!F22 -> P | I22: =IF(G22<>"",-(F22-G22)/F22+1, "") -> 0.981 | J22: 2 x 374u + 1 x 233u | K22: 46085 | L22: =IF(N22<>"","ENTREGADO",IF(K22<>"","LISTO PARA ENTREGAR","EN PROCESO" )) -> ENTREGADO | M22: F26045 | N22: 3366
A23: =PEDIDOS!A23 -> 26002 | B23: =PEDIDOS!B23 -> 46052 | C23: =PEDIDOS!C23 | D23: =PEDIDOS!D23 -> ALL BEAUTY | E23: =PEDIDOS!E23 -> CREMA DE ORDEÑE X 300gr | F23: =PEDIDOS!G23 -> 1500 | G23: 1483 | H23: =PEDIDOS!F23 -> M | I23: =IF(G23<>"",-(F23-G23)/F23+1, "") -> 0.98866667 | J23: 74X20 1X3 | K23: 46080 | L23: =IF(N23<>"","ENTREGADO",IF(K23<>"","LISTO PARA ENTREGAR","EN PROCESO" )) -> ENTREGADO | M23: F26039 | N23: 3366
A24: =PEDIDOS!A24 -> 26003 | B24: =PEDIDOS!B24 -> 46043 | C24: =PEDIDOS!C24 -> 103 | D24: =PEDIDOS!D24 -> UNICA | E24: =PEDIDOS!E24 -> CREMA ENEBRO | F24: =PEDIDOS!G24 -> 500 | G24: =9*50+55 -> 505 | H24: =PEDIDOS!F24 -> M | I24: =IF(G24<>"",-(F24-G24)/F24+1, "") -> 1.01 | J24: 9 x 50u + 1 x 55u | K24: 46101 | L24: =IF(N24<>"","ENTREGADO",IF(K24<>"","LISTO PARA ENTREGAR","EN PROCESO" )) -> ENTREGADO | M24: 200301 | N24: 250326
A25: =PEDIDOS!A25 -> 26004 | B25: =PEDIDOS!B25 -> 46066 | C25: =PEDIDOS!C25 -> 15114 | D25: =PEDIDOS!D25 -> THELMA Y LOUISE | E25: =PEDIDOS!E25 -> SERUM BIFASICO JOJOBA-POMELO | F25: =PEDIDOS!G25 -> 3024 | G25: =30*100+15 -> 3015 | H25: =PEDIDOS!F25 -> M | I25: =IF(G25<>"",-(F25-G25)/F25+1, "") -> 0.99702381 | J25: 30 x 100u + 1 x 15u | K25: 46099 | L25: =IF(N25<>"","ENTREGADO",IF(K25<>"","LISTO PARA ENTREGAR","EN PROCESO" )) -> ENTREGADO | M25: M26024 | N25: 3402
A26: =PEDIDOS!A26 -> 26004 | B26: =PEDIDOS!B26 -> 46066 | C26: =PEDIDOS!C26 -> 15114 | D26: =PEDIDOS!D26 -> THELMA Y LOUISE | E26: =PEDIDOS!E26 -> SERUM BIFASICO PEPINO-HAMAMELIS | F26: =PEDIDOS!G26 -> 3024 | G26: =29*100+103 -> 3003 | H26: =PEDIDOS!F26 -> M | I26: =IF(G26<>"",-(F26-G26)/F26+1, "") -> 0.99305556 | J26: 29 x 100u + 1 x 103u | K26: 46107 | L26: =IF(N26<>"","ENTREGADO",IF(K26<>"","LISTO PARA ENTREGAR","EN PROCESO" )) -> ENTREGADO | M26: M26083 | N26: 3413
A27: =PEDIDOS!A27 -> 26004 | B27: =PEDIDOS!B27 -> 46066 | C27: =PEDIDOS!C27 -> 15114 | D27: =PEDIDOS!D27 -> THELMA Y LOUISE | E27: =PEDIDOS!E27 -> SERUM BIFASICO LAVANDA-BLUEBERRY | F27: =PEDIDOS!G27 -> 3024 | G27: =30*100+16 -> 3016 | H27: =PEDIDOS!F27 -> M | I27: =IF(G27<>"",-(F27-G27)/F27+1, "") -> 0.9973545 | J27: 30 x 100u + 1 x 16u | K27: 46093 | L27: =IF(N27<>"","ENTREGADO",IF(K27<>"","LISTO PARA ENTREGAR","EN PROCESO" )) -> ENTREGADO | M27: M26022 | N27: 3387
A28: =PEDIDOS!A28 -> 26004 | B28: =PEDIDOS!B28 -> 46066 | C28: =PEDIDOS!C28 -> 15114 | D28: =PEDIDOS!D28 -> THELMA Y LOUISE | E28: =PEDIDOS!E28 -> SERUM BIFASICO ROSA MOSQUETA-ROSAS | F28: =PEDIDOS!G28 -> 3024 | G28: =30*100+13 -> 3013 | H28: =PEDIDOS!F28 -> M | I28: =IF(G28<>"",-(F28-G28)/F28+1, "") -> 0.99636243 | J28: 30 x 100u + 1 x 13u | K28: 46108 | L28: =IF(N28<>"","ENTREGADO",IF(K28<>"","LISTO PARA ENTREGAR","EN PROCESO" )) -> ENTREGADO | M28: M26084 | N28: 3413
A29: =PEDIDOS!A29 -> 26005 | B29: =PEDIDOS!B29 -> 46071 | C29: =PEDIDOS!C29 -> 772 | D29: =PEDIDOS!D29 -> CAV | E29: =PEDIDOS!E29 -> SHAMPOO BIO MOLECULAR X400ML VITAMIN SHOCK | F29: =PEDIDOS!G29 -> 700 | G29: =10*12+7 -> 127 | H29: =PEDIDOS!F29 -> M | I29: =IF(G29<>"",-(F29-G29)/F29+1, "") -> 0.18142857 | J29: 10 x 12u + 1 x 7u | K29: 46087 | L29: =IF(N29<>"","ENTREGADO",IF(K29<>"","LISTO PARA ENTREGAR","EN PROCESO" )) -> ENTREGADO | M29: E26064 | N29: 3403
A30: =PEDIDOS!A30 -> 26005 | B30: =PEDIDOS!B30 -> 46071 | C30: =PEDIDOS!C30 -> 772 | D30: =PEDIDOS!D30 -> CAV | E30: =PEDIDOS!E30 -> SERUM BIO MOLUECULAR X30ML VITAMIN SHOCK | F30: =PEDIDOS!G30 -> 300 | G30: =70+65+2*82+47 -> 346 | H30: =PEDIDOS!F30 -> P | I30: =IF(G30<>"",-(F30-G30)/F30+1, "") -> 1.1533333 | J30: 1 x 70 + 1 x 65u + 2 x 82u + 1 x 47u | K30: 46094 | L30: =IF(N30<>"","ENTREGADO",IF(K30<>"","LISTO PARA ENTREGAR","EN PROCESO" )) -> ENTREGADO | M30: M26009 | N30: 3386
A31: =PEDIDOS!A31 -> 26005 | B31: =PEDIDOS!B31 -> 46071 | C31: =PEDIDOS!C31 -> 772 | D31: =PEDIDOS!D31 -> CAV | E31: =PEDIDOS!E31 -> BALSAMO X400ML BIOMIC C/ ACIDO HIAL + CAPIMAX | F31: =PEDIDOS!G31 -> 400 | H31: =PEDIDOS!F31 -> M | I31: =IF(G31<>"",-(F31-G31)/F31+1, "") | L31: =IF(N31<>"","ENTREGADO",IF(K31<>"","LISTO PARA ENTREGAR","EN PROCESO" )) -> EN PROCESO
A32: =PEDIDOS!A32 -> 26005 | B32: =PEDIDOS!B32 -> 46071 | C32: =PEDIDOS!C32 -> 772 | D32: =PEDIDOS!D32 -> CAV | E32: =PEDIDOS!E32 -> MASCARA BIO MOLECULAR VITAMIN SHOCK X300ML | F32: =PEDIDOS!G32 -> 700 | G32: =238+21*15 -> 553 | H32: =PEDIDOS!F32 -> M | I32: =IF(G32<>"",-(F32-G32)/F32+1, "") -> 0.79 | J32: 15x15 1x13u/21X15 | K32: 46097 | L32: =IF(N32<>"","ENTREGADO",IF(K32<>"","LISTO PARA ENTREGAR","EN PROCESO" )) -> ENTREGADO | M32: M26045 | N32: 3386 / 3388
A33: =PEDIDOS!A33 -> 26006 | B33: =PEDIDOS!B33 -> 46071 | C33: =PEDIDOS!C33 -> 14329 | D33: =PEDIDOS!D33 -> JACTANS - DISNEY | E33: =PEDIDOS!E33 -> DSH-41823-Shampoo infantil fco pvc x45ml | F33: =PEDIDOS!G33 -> 3000 | G33: =26*110+29 -> 2889 | H33: =PEDIDOS!F33 -> M | I33: =IF(G33<>"",-(F33-G33)/F33+1, "") -> 0.963 | J33: 26x110 1x29 | K33: 46086 | L33: =IF(N33<>"","ENTREGADO",IF(K33<>"","LISTO PARA ENTREGAR","EN PROCESO" )) -> ENTREGADO | M33: M26002 | N33: 3381
A34: =PEDIDOS!A34 -> 26006 | B34: =PEDIDOS!B34 -> 46071 | C34: =PEDIDOS!C34 -> 14329 | D34: =PEDIDOS!D34 -> JACTANS - DISNEY | E34: =PEDIDOS!E34 -> DES-41823-Espuma de Baño infantil fco pvc x45ml | F34: =PEDIDOS!G34 -> 3000 | G34: 2885 | H34: =PEDIDOS!F34 -> M | I34: =IF(G34<>"",-(F34-G34)/F34+1, "") -> 0.96166667 | J34: 26X110 1X25 | K34: 46085 | L34: =IF(N34<>"","ENTREGADO",IF(K34<>"","LISTO PARA ENTREGAR","EN PROCESO" )) -> ENTREGADO | M34: M26001 | N34: 3381
A35: =PEDIDOS!A35 -> 26007 | B35: =PEDIDOS!B35 -> 46071 | C35: =PEDIDOS!C35 | D35: =PEDIDOS!D35 -> BL COSMETICS | E35: =PEDIDOS!E35 -> ALISADO EXPERT | F35: =PEDIDOS!G35 -> 500 | G35: 500 | H35: =PEDIDOS!F35 -> M | I35: =IF(G35<>"",-(F35-G35)/F35+1, "") -> 1 | J35: 18x27 1x14 | K35: 46085 | L35: =IF(N35<>"","ENTREGADO",IF(K35<>"","LISTO PARA ENTREGAR","EN PROCESO" )) -> ENTREGADO | M35: M26007 | N35: 3378
A36: =PEDIDOS!A36 -> 26007 | B36: =PEDIDOS!B36 -> 46071 | C36: =PEDIDOS!C36 | D36: =PEDIDOS!D36 -> BL COSMETICS | E36: =PEDIDOS!E36 -> ALISADO EXPERT X1KG | F36: =PEDIDOS!G36 -> 500 | G36: 460 | H36: =PEDIDOS!F36 -> M | I36: =IF(G36<>"",-(F36-G36)/F36+1, "") -> 0.92 | J36: 46X10 | K36: 46087 | L36: =IF(N36<>"","ENTREGADO",IF(K36<>"","LISTO PARA ENTREGAR","EN PROCESO" )) -> ENTREGADO | M36: M26007 | N36: 3378
A37: =PEDIDOS!A37 -> 26007 | B37: =PEDIDOS!B37 -> 46071 | C37: =PEDIDOS!C37 | D37: =PEDIDOS!D37 -> BL COSMETICS | E37: =PEDIDOS!E37 -> ALISADO KERATIN | F37: =PEDIDOS!G37 -> 1000 | G37: 1003 | H37: =PEDIDOS!F37 -> M | I37: =IF(G37<>"",-(F37-G37)/F37+1, "") -> 1.003 | J37: 35X28 1X23 | K37: 46090 | L37: =IF(N37<>"","ENTREGADO",IF(K37<>"","LISTO PARA ENTREGAR","EN PROCESO" )) -> ENTREGADO | M37: M26008 | N37: 3378
A38: =PEDIDOS!A38 -> 26008 | B38: =PEDIDOS!B38 -> 46071 | C38: =PEDIDOS!C38 -> P00147 | D38: =PEDIDOS!D38 -> LURE | E38: =PEDIDOS!E38 -> GOLD MASK | F38: =PEDIDOS!G38 -> 600 | G38: 585 | H38: =PEDIDOS!F38 -> M | I38: =IF(G38<>"",-(F38-G38)/F38+1, "") -> 0.975 | J38: 10X36/ 6X36 1X9 | K38: 46080 | L38: =IF(N38<>"","ENTREGADO",IF(K38<>"","LISTO PARA ENTREGAR","EN PROCESO" )) -> ENTREGADO | M38: F26025 | N38: 3357 / 3361
A39: =PEDIDOS!A39 -> 26009 | B39: =PEDIDOS!B39 -> 46071 | C39: =PEDIDOS!C39 -> TCL 2025-02-28 | D39: =PEDIDOS!D39 -> THE CHEMIST LOOK | E39: =PEDIDOS!E39 -> MANCHAS 5ML - PIGMENT PROTOCOL | F39: =PEDIDOS!G39 -> 1000 | G39: =250+87+20 -> 357 | H39: =PEDIDOS!F39 -> P | I39: =IF(G39<>"",-(F39-G39)/F39+1, "") -> 0.357 | J39: 1 x 250u + 1 x 87u + 1 x 20u | K39: 46100 | L39: =IF(N39<>"","ENTREGADO",IF(K39<>"","LISTO PARA ENTREGAR","EN PROCESO" )) -> ENTREGADO | M39: M26015 | N39: 3397
A40: =PEDIDOS!A40 -> 26009 | B40: =PEDIDOS!B40 -> 46071 | C40: =PEDIDOS!C40 -> TCL 2025-02-28 | D40: =PEDIDOS!D40 -> THE CHEMIST LOOK | E40: =PEDIDOS!E40 -> MANCHAS 30ML - PIGMENT PROTOCOL | F40: =PEDIDOS!G40 -> 2000 | G40: =18*110+10 -> 1990 | H40: =PEDIDOS!F40 -> P | I40: =IF(G40<>"",-(F40-G40)/F40+1, "") -> 0.995 | J40: 18 x 110u + 1 x 10u | K40: 46100 | L40: =IF(N40<>"","ENTREGADO",IF(K40<>"","LISTO PARA ENTREGAR","EN PROCESO" )) -> ENTREGADO | M40: M26015 | N40: 3397
...

Sheet INGRESOS
A1: FECHA | B1: N°OC | C1: CLIENTE | D1: PRODUCTO | E1: Q | H1: ME | I1: FECHA ME | J1: MP | K1: FECHA MP | L1: OBSERVACIONES
A2: =PEDIDOS!B2 -> 46035 | B2: =PEDIDOS!C2 -> 163 | C2: =PEDIDOS!D2 -> THE MINIMAL CO | D2: =PEDIDOS!E2 -> MILKY TONER | E2: =PEDIDOS!G2 -> 900 | H2: COMPLETO | I2: 46040
A3: =PEDIDOS!B3 -> 46035 | B3: =PEDIDOS!C3 -> 14297 | C3: =PEDIDOS!D3 -> JACTANS | D3: =PEDIDOS!E3 -> JS-941 AGUA MICELAR BIFASCIA | E3: =PEDIDOS!G3 -> 1000 | H3: COMPLETO | I3: 46038
A4: =PEDIDOS!B4 -> 46035 | B4: =PEDIDOS!C4 -> 15074 | C4: =PEDIDOS!D4 -> THELMA Y LOUISE | D4: =PEDIDOS!E4 -> AGUA TERMAL | E4: =PEDIDOS!G4 -> 2940 | H4: COMPLETO | I4: 46044
A5: =PEDIDOS!B5 -> 46035 | B5: =PEDIDOS!C5 | C5: =PEDIDOS!D5 -> LIORA | D5: =PEDIDOS!E5 -> CREMA PARA PEINAR RULOS | E5: =PEDIDOS!G5 -> 170 | H5: COMPLETO | I5: 30/02/2026
A6: =PEDIDOS!B6 -> 46042 | B6: =PEDIDOS!C6 -> P01203 | C6: =PEDIDOS!D6 -> BIOESENCIA | D6: =PEDIDOS!E6 -> SERUM ORIGENES | E6: =PEDIDOS!G6 -> 1600 | H6: COMPLETO | I6: 46027
A7: =PEDIDOS!B7 -> 46042 | B7: =PEDIDOS!C7 | C7: =PEDIDOS!D7 -> WSABI | D7: =PEDIDOS!E7 -> SERUM INTIMO | E7: =PEDIDOS!G7 -> 300 | H7: COMPLETO | I7: 46071
A8: =PEDIDOS!B8 -> 46042 | B8: =PEDIDOS!C8 | C8: =PEDIDOS!D8 -> MERMER | D8: =PEDIDOS!E8 -> ACEITE CORPORAL LAVANDA | E8: =PEDIDOS!G8 -> 300 | H8: COMPLETO | I8: 46042
A9: =PEDIDOS!B9 -> 46042 | B9: =PEDIDOS!C9 | C9: =PEDIDOS!D9 -> MERMER | D9: =PEDIDOS!E9 -> ACEITE CORPORAL ALMENDRA | E9: =PEDIDOS!G9 -> 300 | H9: COMPLETO | I9: 46042
A10: =PEDIDOS!B10 -> 46042 | B10: =PEDIDOS!C10 | C10: =PEDIDOS!D10 -> MERMER | D10: =PEDIDOS!E10 -> ACEITE CORPORAL ROSAS | E10: =PEDIDOS!G10 -> 300 | H10: COMPLETO | I10: 46042
A11: =PEDIDOS!B11 -> 46042 | B11: =PEDIDOS!C11 | C11: =PEDIDOS!D11 -> MERMER | D11: =PEDIDOS!E11 -> ACEITE CORPORAL SESAMO | E11: =PEDIDOS!G11 -> 300 | H11: COMPLETO | I11: 46042
A12: =PEDIDOS!B12 -> 46042 | B12: =PEDIDOS!C12 | C12: =PEDIDOS!D12 -> MERMER | D12: =PEDIDOS!E12 -> ACEITE CORPORAL INCIENSO | E12: =PEDIDOS!G12 -> 300 | H12: COMPLETO | I12: 46042
A13: =PEDIDOS!B13 -> 46042 | B13: =PEDIDOS!C13 | C13: =PEDIDOS!D13 -> MERMER | D13: =PEDIDOS!E13 -> ACEITE CORPORAL ARNICA | E13: =PEDIDOS!G13 -> 300 | H13: COMPLETO | I13: 46042
A14: =PEDIDOS!B14 -> 46042 | B14: =PEDIDOS!C14 | C14: =PEDIDOS!D14 -> MERMER | D14: =PEDIDOS!E14 -> LOCION CAPILAR | E14: =PEDIDOS!G14 -> 400 | H14: COMPLETO | I14: 46042
A15: =PEDIDOS!B15 -> 46042 | B15: =PEDIDOS!C15 | C15: =PEDIDOS!D15 -> MERMER | D15: =PEDIDOS!E15 -> SERUM CAPILAR | E15: =PEDIDOS!G15 -> 400 | H15: COMPLETO | I15: 46042
A16: =PEDIDOS!B16 -> 46049 | B16: =PEDIDOS!C16 -> 1708 | C16: =PEDIDOS!D16 -> LABORATORIO ONCE | D16: =PEDIDOS!E16 -> SERUM ACIDO HIALURONICO + NIACINAMIDA | E16: =PEDIDOS!G16 -> 1653 | H16: COMPLETO | I16: 46035
A17: =PEDIDOS!B17 -> 46050 | B17: =PEDIDOS!C17 -> 15098 | C17: =PEDIDOS!D17 -> THELMA Y LOUISE | D17: =PEDIDOS!E17 -> CREMA BIFASICA CHERRY | E17: =PEDIDOS!G17 -> 1640 | H17: COMPLETO | I17: 46052
A18: =PEDIDOS!B18 -> 46052 | B18: =PEDIDOS!C18 | C18: =PEDIDOS!D18 -> ALL BEAUTY | D18: =PEDIDOS!E18 -> SERUM ACIDO HIALURONICO | E18: =PEDIDOS!G18 -> 1000 | H18: COMPLETO
A19: =PEDIDOS!B19 -> 46044 | B19: =PEDIDOS!C19 | C19: =PEDIDOS!D19 -> DWUAM | D19: =PEDIDOS!E19 -> BASE DE MAQUILLAJE TONO 1 | E19: =PEDIDOS!G19 -> 500 | H19: COMPLETO
A20: =PEDIDOS!B20 -> 46071 | B20: =PEDIDOS!C20 -> 6433 | C20: =PEDIDOS!D20 -> HEBURN | D20: =PEDIDOS!E20 -> BRUMA FIJADORA de MAQUILLAJE x 125 cc | E20: =PEDIDOS!G20 -> 600 | H20: COMPLETO
A21: =PEDIDOS!B21 -> 46052 | B21: =PEDIDOS!C21 | C21: =PEDIDOS!D21 -> ALL BEAUTY | D21: =PEDIDOS!E21 -> CREMA FACIAL HIDRATANTE X 50gr (DIA) | E21: =PEDIDOS!G21 -> 1000 | H21: COMPLETO | I21: 30/02/2026
A22: =PEDIDOS!B22 -> 46052 | B22: =PEDIDOS!C22 | C22: =PEDIDOS!D22 -> ALL BEAUTY | D22: =PEDIDOS!E22 -> UNGÜENTO POMADA OLEO 30 + 1 X 10gr | E22: =PEDIDOS!G22 -> 1000 | H22: COMPLETO | I22: 30/02/2026
A23: =PEDIDOS!B23 -> 46052 | B23: =PEDIDOS!C23 | C23: =PEDIDOS!D23 -> ALL BEAUTY | D23: =PEDIDOS!E23 -> CREMA DE ORDEÑE X 300gr | E23: =PEDIDOS!G23 -> 1500 | H23: COMPLETO | I23: 30/02/2026
A24: =PEDIDOS!B24 -> 46043 | B24: =PEDIDOS!C24 -> 103 | C24: =PEDIDOS!D24 -> UNICA | D24: =PEDIDOS!E24 -> CREMA ENEBRO | E24: =PEDIDOS!G24 -> 500 | H24: COMPLETO | I24: 46055
A25: =PEDIDOS!B25 -> 46066 | B25: =PEDIDOS!C25 -> 15114 | C25: =PEDIDOS!D25 -> THELMA Y LOUISE | D25: =PEDIDOS!E25 -> SERUM BIFASICO JOJOBA-POMELO | E25: =PEDIDOS!G25 -> 3024 | H25: COMPLETO | I25: 46084
A26: =PEDIDOS!B26 -> 46066 | B26: =PEDIDOS!C26 -> 15114 | C26: =PEDIDOS!D26 -> THELMA Y LOUISE | D26: =PEDIDOS!E26 -> SERUM BIFASICO PEPINO-HAMAMELIS | E26: =PEDIDOS!G26 -> 3024 | H26: COMPLETO | I26: 46084
A27: =PEDIDOS!B27 -> 46066 | B27: =PEDIDOS!C27 -> 15114 | C27: =PEDIDOS!D27 -> THELMA Y LOUISE | D27: =PEDIDOS!E27 -> SERUM BIFASICO LAVANDA-BLUEBERRY | E27: =PEDIDOS!G27 -> 3024 | H27: COMPLETO | I27: 46084
A28: =PEDIDOS!B28 -> 46066 | B28: =PEDIDOS!C28 -> 15114 | C28: =PEDIDOS!D28 -> THELMA Y LOUISE | D28: =PEDIDOS!E28 -> SERUM BIFASICO ROSA MOSQUETA-ROSAS | E28: =PEDIDOS!G28 -> 3024 | H28: COMPLETO | I28: 46084
A29: =PEDIDOS!B29 -> 46071 | B29: =PEDIDOS!C29 -> 772 | C29: =PEDIDOS!D29 -> CAV | D29: =PEDIDOS!E29 -> SHAMPOO BIO MOLECULAR X400ML VITAMIN SHOCK | E29: =PEDIDOS!G29 -> 700
A30: =PEDIDOS!B30 -> 46071 | B30: =PEDIDOS!C30 -> 772 | C30: =PEDIDOS!D30 -> CAV | D30: =PEDIDOS!E30 -> SERUM BIO MOLUECULAR X30ML VITAMIN SHOCK | E30: =PEDIDOS!G30 -> 300
A31: =PEDIDOS!B31 -> 46071 | B31: =PEDIDOS!C31 -> 772 | C31: =PEDIDOS!D31 -> CAV | D31: =PEDIDOS!E31 -> BALSAMO X400ML BIOMIC C/ ACIDO HIAL + CAPIMAX | E31: =PEDIDOS!G31 -> 400
A32: =PEDIDOS!B32 -> 46071 | B32: =PEDIDOS!C32 -> 772 | C32: =PEDIDOS!D32 -> CAV | D32: =PEDIDOS!E32 -> MASCARA BIO MOLECULAR VITAMIN SHOCK X300ML | E32: =PEDIDOS!G32 -> 700
A33: =PEDIDOS!B33 -> 46071 | B33: =PEDIDOS!C33 -> 14329 | C33: =PEDIDOS!D33 -> JACTANS - DISNEY | D33: =PEDIDOS!E33 -> DSH-41823-Shampoo infantil fco pvc x45ml | E33: =PEDIDOS!G33 -> 3000
A34: =PEDIDOS!B34 -> 46071 | B34: =PEDIDOS!C34 -> 14329 | C34: =PEDIDOS!D34 -> JACTANS - DISNEY | D34: =PEDIDOS!E34 -> DES-41823-Espuma de Baño infantil fco pvc x45ml | E34: =PEDIDOS!G34 -> 3000
A35: =PEDIDOS!B35 -> 46071 | B35: =PEDIDOS!C35 | C35: =PEDIDOS!D35 -> BL COSMETICS | D35: =PEDIDOS!E35 -> ALISADO EXPERT | E35: =PEDIDOS!G35 -> 500 | H35: COMPLETO | I35: 46076
A36: =PEDIDOS!B36 -> 46071 | B36: =PEDIDOS!C36 | C36: =PEDIDOS!D36 -> BL COSMETICS | D36: =PEDIDOS!E36 -> ALISADO EXPERT X1KG | E36: =PEDIDOS!G36 -> 500 | H36: COMPLETO | I36: 46076
A37: =PEDIDOS!B37 -> 46071 | B37: =PEDIDOS!C37 | C37: =PEDIDOS!D37 -> BL COSMETICS | D37: =PEDIDOS!E37 -> ALISADO KERATIN | E37: =PEDIDOS!G37 -> 1000 | H37: COMPLETO | I37: 46076
A38: =PEDIDOS!B38 -> 46071 | B38: =PEDIDOS!C38 -> P00147 | C38: =PEDIDOS!D38 -> LURE | D38: =PEDIDOS!E38 -> GOLD MASK | E38: =PEDIDOS!G38 -> 600 | H38: COMPLETO | I38: 46072
A39: =PEDIDOS!B39 -> 46071 | B39: =PEDIDOS!C39 -> TCL 2025-02-28 | C39: =PEDIDOS!D39 -> THE CHEMIST LOOK | D39: =PEDIDOS!E39 -> MANCHAS 5ML - PIGMENT PROTOCOL | E39: =PEDIDOS!G39 -> 1000
A40: =PEDIDOS!B40 -> 46071 | B40: =PEDIDOS!C40 -> TCL 2025-02-28 | C40: =PEDIDOS!D40 -> THE CHEMIST LOOK | D40: =PEDIDOS!E40 -> MANCHAS 30ML - PIGMENT PROTOCOL | E40: =PEDIDOS!G40 -> 2000
...

Sheet KPI
A1: Fecha | B1: N° OC | C1: CLIENTE | D1: PRODUCTO | E1: Sector | F1: N° LOTE | G1: LEAD TIME | H1: NIVEL DE SERVICIO | I1: Reclamo
A2: =PEDIDOS!B2 -> 46035 | B2: =PEDIDOS!C2 -> 163 | C2: =PEDIDOS!D2 -> THE MINIMAL CO | D2: =PEDIDOS!E2 -> MILKY TONER | E2: =PEDIDOS!F2 -> P | F2: =PEDIDOS!M2 -> F26021 | G2: =-PEDIDOS!B2+EXPEDICION!K2 -> 41 | H2: =EXPEDICION!I2 -> 0.99888889
A3: =PEDIDOS!B3 -> 46035 | B3: =PEDIDOS!C3 -> 14297 | C3: =PEDIDOS!D3 -> JACTANS | D3: =PEDIDOS!E3 -> JS-941 AGUA MICELAR BIFASCIA | E3: =PEDIDOS!F3 -> P | F3: =PEDIDOS!M3 -> F26031 | G3: =-PEDIDOS!B3+EXPEDICION!K3 -> 45 | H3: =EXPEDICION!I3 -> 1.011
A4: =PEDIDOS!B4 -> 46035 | B4: =PEDIDOS!C4 -> 15074 | C4: =PEDIDOS!D4 -> THELMA Y LOUISE | D4: =PEDIDOS!E4 -> AGUA TERMAL | E4: =PEDIDOS!F4 -> P | F4: =PEDIDOS!M4 -> F26041 | G4: =-PEDIDOS!B4+EXPEDICION!K4 -> 48 | H4: =EXPEDICION!I4 -> 0.99047619
A5: =PEDIDOS!B5 -> 46035 | B5: =PEDIDOS!C5 | C5: =PEDIDOS!D5 -> LIORA | D5: =PEDIDOS!E5 -> CREMA PARA PEINAR RULOS | E5: =PEDIDOS!F5 -> P | F5: =PEDIDOS!M5 -> Y26039 | G5: =-PEDIDOS!B5+EXPEDICION!K5 -> 126 | H5: =EXPEDICION!I5 -> 0.86470588
A6: =PEDIDOS!B6 -> 46042 | B6: =PEDIDOS!C6 -> P01203 | C6: =PEDIDOS!D6 -> BIOESENCIA | D6: =PEDIDOS!E6 -> SERUM ORIGENES | E6: =PEDIDOS!F6 -> P | F6: =PEDIDOS!M6 -> 240201 | G6: =-PEDIDOS!B6+EXPEDICION!K6 -> 35 | H6: =EXPEDICION!I6 -> 1.00125
A7: =PEDIDOS!B7 -> 46042 | B7: =PEDIDOS!C7 | C7: =PEDIDOS!D7 -> WSABI | D7: =PEDIDOS!E7 -> SERUM INTIMO | E7: =PEDIDOS!F7 -> P | F7: =PEDIDOS!M7 -> F26049 | G7: =-PEDIDOS!B7+EXPEDICION!K7 -> 45 | H7: =EXPEDICION!I7 -> 0.97666667
A8: =PEDIDOS!B8 -> 46042 | B8: =PEDIDOS!C8 | C8: =PEDIDOS!D8 -> MERMER | D8: =PEDIDOS!E8 -> ACEITE CORPORAL LAVANDA | E8: =PEDIDOS!F8 -> P | F8: =PEDIDOS!M8 -> E26087 | G8: =-PEDIDOS!B8+EXPEDICION!K8 -> 8 | H8: =EXPEDICION!I8 -> 1.6966667
A9: =PEDIDOS!B9 -> 46042 | B9: =PEDIDOS!C9 | C9: =PEDIDOS!D9 -> MERMER | D9: =PEDIDOS!E9 -> ACEITE CORPORAL ALMENDRA | E9: =PEDIDOS!F9 -> P | F9: =PEDIDOS!M9 -> E26088 | G9: =-PEDIDOS!B9+EXPEDICION!K9 -> 8 | H9: =EXPEDICION!I9 -> 1.02
A10: =PEDIDOS!B10 -> 46042 | B10: =PEDIDOS!C10 | C10: =PEDIDOS!D10 -> MERMER | D10: =PEDIDOS!E10 -> ACEITE CORPORAL ROSAS | E10: =PEDIDOS!F10 -> P | F10: =PEDIDOS!M10 -> E26089 | G10: =-PEDIDOS!B10+EXPEDICION!K10 -> 8 | H10: =EXPEDICION!I10 -> 1.01
A11: =PEDIDOS!B11 -> 46042 | B11: =PEDIDOS!C11 | C11: =PEDIDOS!D11 -> MERMER | D11: =PEDIDOS!E11 -> ACEITE CORPORAL SESAMO | E11: =PEDIDOS!F11 -> P | F11: =PEDIDOS!M11 -> E26090 | G11: =-PEDIDOS!B11+EXPEDICION!K11 -> 8 | H11: =EXPEDICION!I11 -> 1.04
A12: =PEDIDOS!B12 -> 46042 | B12: =PEDIDOS!C12 | C12: =PEDIDOS!D12 -> MERMER | D12: =PEDIDOS!E12 -> ACEITE CORPORAL INCIENSO | E12: =PEDIDOS!F12 -> P | F12: =PEDIDOS!M12 -> E26091 | G12: =-PEDIDOS!B12+EXPEDICION!K12 -> 8 | H12: =EXPEDICION!I12 -> 1.02
A13: =PEDIDOS!B13 -> 46042 | B13: =PEDIDOS!C13 | C13: =PEDIDOS!D13 -> MERMER | D13: =PEDIDOS!E13 -> ACEITE CORPORAL ARNICA | E13: =PEDIDOS!F13 -> P | F13: =PEDIDOS!M13 -> E26092 | G13: =-PEDIDOS!B13+EXPEDICION!K13 -> 8 | H13: =EXPEDICION!I13 -> 1.0133333
... A422: =PEDIDOS!B422 | B422: =PEDIDOS!C422 | C422: =PEDIDOS!D422 | D422: =PEDIDOS!E422 | E422: =PEDIDOS!F422 | F422: =PEDIDOS!M422 | G422: =-PEDIDOS!B422+EXPEDICION!K422 -> 0 | H422: =EXPEDICION!I422

Sheet Dashboard
E2: DASHBOARD OPERATIVO · AÑO 2026 | N2: =TODAY() -> 46204 | R2: ANÁLISIS DE CLIENTES · PERFORMANCE OPERATIVA
B5: NIVEL DE SERVICIO | F5: PEDIDOS SIN RECLAMOS | J5: LEAD TIME PROMEDIO | N5: UNIDADES PRODUCIDAS / AÑO | R5: TOP CLIENTES POR CANTIDAD DE PEDIDOS | U5: CLIENTES CON MENOR LEAD TIME
B6: =AVERAGE(KPI!H2:H500) -> 0.98269572 | F6: =1-(COUNTIF(KPI!I2:I31,"R")/COUNTA(KPI!C2:C31)) -> 1 | J6: =AVERAGEIFS(KPI!G2:G1000,KPI!G2:G1000,">0",KPI!G2:G1000,"<100") -> 26.254658 | N6: =SUM(EXPEDICION!G2:G10966) -> 501120 | R6: CLIENTE | S6: PEDIDOS / BARRA | U6: CLIENTE | V6: DÍAS PROM / BARRA
B7: =IF(AVERAGE(KPI!H2:H1000)>=0.97,"✅ CUMPLE | Obj: ≥97%",IF(AVERAGE(KPI!H2:H1000)>=0.96,"⚠️ ATENCIÓN | Obj: ≥97%","🔴 CRÍTICO | Obj: ≥95%")) -> ✅ CUMPLE | Obj: ≥97% | F7: =IF(1-(COUNTIF(KPI!I2:I31,"R")/COUNTA(KPI!C2:C31))>=0.95,"✅ CUMPLE | Obj: >95%","⚠️ REVISAR | Obj: >95%") -> ✅ CUMPLE | Obj: >95% | J7: =IF(AVERAGEIFS(KPI!G2:G1000,KPI!G2:G1000,">0",KPI!G2:G1000,"<100")<=25,"✅ CUMPLE | Obj: ≤25 días","⚠️ ATENCIÓN | Obj: ≤25 días") -> ⚠️ ATENCIÓN | Obj: ≤25 días | N7: =TEXT(SUM(EXPEDICION!G2:G10966),"#,##0")&" unidades producidas" -> 501.120 unidades producidas | R7: =CALCULOS_CLIENTES!E2 -> THELMA Y LOUISE | S7: =IF(CALCULOS_CLIENTES!F2="","",CALCULOS_CLIENTES!F2&" "&REPT("█",ROUND(CALCULOS_CLIENTES!F2/CALCULOS_CLIENTES!$F$2*20,0))) -> 60 ████████████████████ | U7: =CALCULOS_CLIENTES!H2 -> DWUAM | V7: =IF(CALCULOS_CLIENTES!I2="","",ROUND(CALCULOS_CLIENTES!I2,1)&" d "&REPT("█",ROUND(CALCULOS_CLIENTES!I2/CALCULOS_CLIENTES!$I$11*20,0))) -> 7 d █████████
