Workbook

Sheet ELABORACION
B1: Lunes | D1: Martes | F1: Miércoles | H1: Jueves | J1: Viernes
B2: 16 | D2: 17 | F2: 18 | H2: 19 | J2: 20
B3: Febrero | D3: Febrero | F3: Febrero | H3: Febrero | J3: Febrero
B4: CRISTIAN
F5: LAB ONCE | H5: NIZA | J5: THELMA Y LOUISE
F6: SERUM AH+NIA | H6: MIXOLOGI INFLAMADA | J6: CREMA CHERRY
F7: 55KG | H7: 95KG | J7: 265KG TOTAL
H8: MIXOLOGI DESVITAL
F9: ALL BEAUTY | H9: 95KG | J9: JACTANS
F10: SERUM AH | H10: MIXOLOGI DESHIDRATADA | J10: AGUA MIC BIFASICA
F11: 33kg | H11: 95KG | J11: 130KG
B13: NICOLAS
F14: WSABI | H14: ALL BEAUTY | J14: THELMA Y LOUISE
F15: SERUM TENSOR 17KG (NUEVA FORMULA) | H15: CREMA DE ORDEÑE | J15: AGUA TERMAL 320KG
H16: 450KG | J16: TATWO
J17: LOCION PIERCING 50KG
F18: NATCEUTICALS | H18: ORIGINIAL BLACK
F19: GEL LIMPIEADOR 45KG | H19: AFTER COOL WATER
F20: EMULSION LIMPIEZA 45KG | H20: 800
B24: Lunes | D24: Martes | F24: Miércoles | H24: Jueves | J24: Viernes
B25: 23 | D25: 24 | F25: 25 | H25: 26 | J25: 27
B26: Febrero | D26: Febrero | F26: Febrero | H26: Febrero | J26: Febrero
B27: CRISTIAN
B28: ALL BEAUTY | D28: INTENCIONAL | F28: BL COSMETICS | H28: THE CHEMIST LOOK | J28: CAV
B29: CREMA HIDRATANTE | D29: CREMA DE ORDEÑE | F29: ALISADO EXPERT | H29: SERUM VITAMINA C 50KG | J29: SHAMPOO 420KG
B30: 55KG | D30: 530KG | F30: 680KG (hay sorante ver) | H30: SERUM NIACI 55KG
B31: MERMER | F31: ALISADO KERATIN 310KG
B32: SERUM CAPILAR 44KG | H32: SARAC
B33: RHIFT | D33: THE CHEMIST LOOK | H33: FRACCIONADO BUTTER
B34: SERUM DESPIG 22KG | D34: SERUM HYALU 40KG
B36: NICOLAS
B37: LURE | D37: ALL BEAUTY | F37: SARAC | H37: DEL ARCA BOTANICA
B38: GOLD MASK 70KG | D38: OLEO 30+1 12KG | F38: FRACCIONADO SUGAR | H38: SH FORTALECEDOR
B39: WSABI | D39: KALA | H39: 25KG
B40: SERUM INTIMO 10kg | D40: AGUA DE ROSAS 65KG | F40: MERMER | H40: CAV
B41: SARAC | D41: BIOESENCIA | F41: LOCION CAPILAR 44KG | H41: ACONDICIONADOR 100KG | J41: TYL
B42: CREMA EXF DAMAZCO | D42: CREMA BABA CARACOL | J42: SERUM ANTIAGE 70KG
B43: 20KG | D43: 55KG | J43: SERUM DESCONG 70KG
B47: Lunes | D47: Martes | F47: Miércoles | H47: Jueves | J47: Viernes
B48: 2 | D48: 3 | F48: 4 | H48: 5 | J48: 6
...

Sheet ACONDICIONAMIENTO
B1: Lunes | D1: Martes | F1: Miércoles | H1: Jueves | J1: Viernes
B2: 16 | D2: 17 | F2: 18 | H2: 19 | J2: 20
B3: Febrero | D3: Febrero | F3: Febrero | H3: Febrero | J3: Febrero
D4: ENVASADO CONSUMO MASIVO
F5: CAV | H5: BIOESENCIA | J5: ORIGINAL BLACK
F6: SHAMPOO X400ML resto | H6: SHAMPOO BABAY | J6: AFTER SHAVE AQUA
F7: CONDITIONER X400 100 | H7: 500 x250ml | J7: 3500
F9: THELMA Y LOUISE | H9: BIOESENCIA | J9: BIOESENCIA
F10: EXFOLIANTE ARROZ | H10: SERUM PROBIOTICS | J10: SERUM ORIGINES
F11: 6400 | H11: 1000x30ml | J11: 1600x30ml
F13: ORIGINAL BLACK | H13: ORIGINAL BLACK | J13: ORIGINAL BLACK
F14: AFTER SHAVE AQUA | H14: AFTER SHAVE AQUA | J14: AFTER SHAVE AQUA
F15: 3500 | H15: 3500 | J15: 3500
D16: ENVASADO PRODUCTOS PREMIUN
F20: TMCO | H20: ALL BEAUTY | J20: LABORATORIO ONCE
F21: MILKY TONER | H21: SERUM AH 1000x30ml | J21: SERUM AH + NIA
F22: 900 x100ml | J22: 1653 x30ml
B26: Lunes | D26: Martes | F26: Miércoles | H26: Jueves | J26: Viernes
B27: 23 | D27: 24 | F27: 25 | H27: 26 | J27: 27
B28: Febrero | D28: Febrero | F28: Febrero | H28: Febrero | J28: Febrero
D29: ENVASADO CONSUMO MASIVO
B30: NIZA | D30: JACTANS | F30: TYL | H30: ALL BEAUTY | J30: ALL BEAUTY
B31: MOXOLOGI X3 | D31: AGUA MICELAR BIFASICA | F31: CREMA BIFASICA CHERRY | H31: CREMA DE ORDEÑE | J31: CREMA DE ORDEÑE
B32: 300 C/U x300ml | D32: 1000x105ml | F32: 1640 | H32: 1500x300ml | J32: 1500x300ml
B34: ORIGINAL BLACK | D34: ALL BEAUTY | F34: TYL | H34: LURE | J34: THELMA Y LOUISE
B35: AFTER SHAVE COOL WAT | D35: CREMA HIDRATANTE | F35: CREMA BIFASICA CHERRY | H35: GOLD MASK | J35: AGUA TERMAL
B36: 2000 | D36: 1000 x50ml | F36: 1640 | H36: 600x100ml | J36: 2940 x100ml
J37: YOUTHFUL VIDEOS!!
B38: ORIGINAL BLACK | D38: ALL BEAUTY | F38: TATWO | H38: DEL ARCA BOTANICA | J38: AGUEDA REY- YOUTHFUL
B39: AFTER SHAVE COOL WAT | D39: OLEO 30+1 1000X10ML | F39: LOCION PARA PIERCING | H39: SH SOLIDO FORTALECEDOR | J39: BRUMA FACIAL
B40: 2000 | F40: 1500 x30ml | J40: 1000 x125ml / 1000x75ml
D41: VIDEOS NATCEUTCALS!! | F41: ENVASADO PRODUCTOS PREMIUN
B42: RHIFT | D42: NATCEUTICALS | F42: RHIFT
B43: VACIADO 400 | D43: LIMPIADORA 200x200ml | F43: SERUM DESPIGMENTANTE 400
D44: GEL LIMPIADOR 200x200ml
B45: LABORATORIO ONCE | F45: AGUEDA REY- YOUTHFUL | H45: AGUEDA REY- YOUTHFUL | J45: THE CHEMIST LOOK
B46: VACIADO | F46: CREMA DIA 1000x50 | H46: SERUM RETINOL 1000x30ml | J46: SERUM HYALU 2400x15ml
B47: SERUM ACIDO GLICOLICO | F47: SERUM AH 1000x30ml | H47: SERUM VIT C 1000x30ml
F48: HACER VIDEOS DE YOUTHFUL!!
B51: Lunes | D51: Martes | F51: Miércoles | H51: Jueves | J51: Viernes
...

Sheet ENTREGAS
B1: FECHA | C1: CLIENTE | D1: PRODUCTO | E1: CANTIDAD
B2: 46072 | C2: TSU | D2: SERUMS X3 | E2: 300
B3: 46073 | C3: OCEAN SKIN | D3: SERUM HIDRATANTE | E3: 500
B4: 46076 | C4: JACTANS-DISNEY | D4: PERFUME REY LEON 5ML | E4: 1000
B5: 46077 | C5: TMCO | D5: MILKY TONER | E5: 900
B6: 46077 | C6: BIOESENCIA | D6: SERUM ORIGENES | E6: 1600
B7: 46077 | C7: BIOESENCIA | D7: SERUM PROBIOTICS | E7: 1000
B8: 46077 | C8: BIOESENCIA | D8: SHAMPOO BABY | E8: 500
B9: 46078 | C9: NIZA | D9: MIXOLOGY X3 | E9: 900
C10: NATCEUTICALS | D10: GEL + EMULSION DE LIMP | E10: 400
B11: 46079 | C11: ALL BEAUTY | D11: SERUM AH | E11: PARCIAL
B12: 46079 | C12: ALL BEAUTY | D12: CREMA HIDRATANTE | E12: PARCIAL
B13: 46080 | C13: RHIFT | D13: SERUM DESPIGMENTANTE | E13: 400
B14: 46080 | C14: BOR | D14: CREMA VITAMINADA | E14: 150
B15: 46080 | C15: LURE | D15: GOLD MASK | E15: 600
B16: 46080 | C16: JACTANS | D16: AGUA MICELAR BIFASICA | E16: 1000
B17: 46080 | C17: TSU | D17: SERUMS X3 | E17: 3000
B18: 46080 | C18: CAV | D18: SHAMPOO | E18: 22
B19: 46080 | C19: CAV | D19: ACONDICIONADOR | E19: 200
B20: 46084 | C20: LAB ONCE | D20: SERUM AH + NIA | E20: 1600
B21: 46084 | C21: TATWO | D21: LOCION PARA PIERCING | E21: 1500
B22: 46086 | C22: YOUTHFUL | D22: SERUMS X3 | E22: 3000
B23: 46086 | C23: YOUTHFUL | D23: BRUMAS X2 | E23: 2000
B24: 46086 | C24: YOUTHFUL | D24: CREMA DIA | E24: 1000
... B51: 46094 | C51: TYL | D51: SERUM BIFASICO BLUEBERRY | E51: 3024
B52: 46094 | C52: TYL | D52: ALCOHOL EN GEL SANDIA | E52: PARCIAL
B53: 46094 | C53: TYL | D53: ALCOHOL EN GEL CHICLE | E53: PARCIAL
B54: 46094 | C54: CAV | D54: SHAMPOO / CONDITIONER KG | E54: 300
B55: 46094 | C55: CAV | D55: SERUM VITAMIN SHOCK | E55: 300
B56: 46094 | C56: CAV | D56: MASCARA VITAMIN SHOCK | E56: PARCIAL
B57: 46097 | C57: LAB ONCE | D57: GEL UNIESFERAS VIT C | E57: 2000
B58: 46097 | C58: TGF | D58: CREMA CLARITÉ | E58: 1000
B59: 46098 | C59: COSMECEUTICALS | D59: REPARADOR DE OJERAS | E59: 550
B60: 46098 | C60: BIOESENCIA | D60: CREMA VEGAN | E60: 1000
B61: 46098 | C61: BIOESENCIA | D61: BRUMA ORIGENES | E61: 1000
B62: 46099 | C62: CRISLY | D62: CREMA AVENA | E62: 300
B63: 46098 | C63: PROF BEAUTY | D63: GEL NEUTRO | E63: 500
B64: 46099 | C64: WSABI | D64: TONICO CORPORAL | E64: 1000
B65: 46099 | C65: WSABI | D65: SERUM VITAMINA C | E65: 300
B66: 46099 | C66: WSABI | D66: CONTORNO DE OJOS | E66: 480
...

Sheet QACONDDIA
B2: FEBRERO 2026
B3: FECHA | C3: PRODUCTO | D3: CANTIDAD | E3: RESPONSABLE
B4: 46071 | C4: TMCO MILKY TONER | D4: 902
C5: CAV ACONDICIONADOR | D5: 160 | E5: JOAQUIN
C6: CAV SHAMPOO | D6: 150 | E6: JOAQUIN
C7: TYL EXFOLIANTE ARRZ | D7: 1258 | E7: NICOLAS M
C8: BIOESENCIA SHAMPOO BABY | D8: 486 | E8: JOAQUIN
B9: 46072 | C9: TYL EXFOLIANTE ARRZ | D9: 401 | E9: JOAQUIN
C10: BIOESENCIA SERUM PROBIOTICS | D10: 1001 | E10: JOAQUIN
C11: BIOSENCIA SERUM ORIGENES | D11: 300 | E11: JOAQUIN
B12: 46073 | C12: BIOSENCIA SERUM ORIGENES | D12: 1100 | E12: JOAQUIN
C13: F.ONCE SERUM HIAL-NIACINAMIDA | D13: 1552
C14: NIZA MIXOLOGY INFLAMADA | D14: 300 | E14: JOAQUIN
C15: ORIGINAL BLACK AFTER SHAVE AZUL | D15: 500 | E15: NICOLAS M
B16: 46076 | C16: ORIGINAL BLACK AFTER SHAVE AZUL | D16: 600 | E16: NICOLAS M
C17: NIZA MIXOLOGY DEVITALIZADA | D17: 300 | E17: JOAQUIN
C18: NIZA MIXOLOGY SENSIBLE Y ACT | D18: 300 | E18: JOAQUIN
C19: ORIGINAL BLACK AFTER SHAVE VIOLETA | D19: 944 | E19: NICOLAS M
C20: ORIGINAL BLACK AFTER SHAVE VIOLETA | D20: 1000 | E20: AGUSTINA H
C21: ORIGINAL BLACK AFTER SHAVE AZUL | D21: 500 | E21: AGUSTINA H
B22: 46077 | C22: JACTANS AGUA BIFASICA | D22: 384 | E22: AGUSTINA H
C23: ALL BEAUTY CREMA HIDRATANTE | D23: 1000 | E23: JOAQUIN
C24: ALL BEAUTY OLEO 30+1 | D24: 997 | E24: NICOLAS M
C25: TATWO LOCION PIRCING | D25: 1200 | E25: AGUSTINA H
C26: YOUTHFUL SERUM HYDRA | D26: 954 | E26: NICOLAS Y
C27: YOUTHFUL SERUM VIT C | D27: 1074 | E27: NICOLAS Y
B28: 46078 | C28: TYL CREMA BIFASICA | D28: 1073 | E28: JOAQUIN
C29: TYL CREMA BIFASICA | D29: 1073 | E29: NICOLAS M
C30: JACTANS AGUA BIFASICA | D30: 1011 | E30: AGUSTINA H
C31: RHIFT SERUM DESPIGMENTANTE | D31: 346 | E31: NICOLAS Y
C32: NATCEUTICALS GEL LIMPIADOR | D32: 200 | E32: NICOLAS Y
C33: NATCEUTICALS CREMA DE LIMPIEZA | D33: 197 | E33: NICOLAS Y
C34: YOUTHFUL GLOW CREMA DIA | D34: 200 | E34: AGUSTINA H
C35: YOUTHFUL BRUMA FACIAL 125 | D35: 450 | E35: AGUSTINA H
B36: 46079 | C36: TYL CREMA BIFASICA | D36: 156 | E36: NICOLAS M
C37: TYL CREMA BIFASICA | D37: 156 | E37: JOAQUIN
C38: YOUTHFUL BRUMA FACIAL 125ML | D38: 594 | E38: AGUSTINA H
C39: YOUTHFUL BRUMA FACIAL 75ML | D39: 970 | E39: AGUSTINA H
C40: LURE GOLD MASK | D40: 450 | E40: NICOLAS M
C41: ALL BEAUTY CREMA ORDEÑE | D41: 600 | E41: JOAQUIN
...

Sheet DB
A1: 46023 | B1: 📊 DASHBOARD DE PRODUCTIVIDAD · ACONDICIONAMIENTO · 2026
A2: 46069 | B2: Sistema automático de seguimiento de envasado | Laboratorio Genus | W2: MES | X2: TOTAL | Y2: JOAQUIN | Z2: NICOLAS M | AA2: AGUSTINA H | AB2: NICOLAS Y | AC2: MASIVO | AD2: PREMIUM
A3: 46070 | W3: FEBRERO | X3: =SUMIFS(QACONDDIA!$D$4:$D$52,QACONDDIA!$E$4:$E$52,"<>") -> 30285 | Y3: =SUMIFS(QACONDDIA!$D$4:$D$52,QACONDDIA!$E$4:$E$52,"JOAQUIN") -> 8210 | Z3: =SUMIFS(QACONDDIA!$D$4:$D$52,QACONDDIA!$E$4:$E$52,"NICOLAS M") -> 6113 | AA3: =SUMIFS(QACONDDIA!$D$4:$D$52,QACONDDIA!$E$4:$E$52,"AGUSTINA H") -> 7981 | AB3: =SUMIFS(QACONDDIA!$D$4:$D$52,QACONDDIA!$E$4:$E$52,"NICOLAS Y") -> 7981 | AC3: =Y3+Z3+AA3 -> 22304 | AD3: =AB3 -> 7981
A4: 46105 | B4: ▌ K P I S | W4: MARZO | X4: =SUMIFS(QACONDDIA!$D$56:$D$167,QACONDDIA!$E$56:$E$167,"<>") -> 84203 | Y4: =SUMIFS(QACONDDIA!$D$56:$D$167,QACONDDIA!$E$56:$E$167,"JOAQUIN") -> 13823 | Z4: =SUMIFS(QACONDDIA!$D$56:$D$167,QACONDDIA!$E$56:$E$167,"NICOLAS M") -> 25948 | AA4: =SUMIFS(QACONDDIA!$D$56:$D$167,QACONDDIA!$E$56:$E$167,"AGUSTINA H") -> 14745 | AB4: =SUMIFS(QACONDDIA!$D$56:$D$167,QACONDDIA!$E$56:$E$167,"NICOLAS Y") -> 29687 | AC4: =Y4+Z4+AA4 -> 54516 | AD4: =AB4 -> 29687
A5: 46114 | B5: 📦 | G5: 🏭 | L5: ⭐ | Q5: 📅 | W5: ABRIL | X5: =SUMIFS(QACONDDIA!$D$169:$D$278,QACONDDIA!$E$169:$E$278,"<>") -> 115488 | Y5: =SUMIFS(QACONDDIA!$D$169:$D$278,QACONDDIA!$E$169:$E$278,"JOAQUIN") -> 4848 | Z5: =SUMIFS(QACONDDIA!$D$169:$D$278,QACONDDIA!$E$169:$E$278,"NICOLAS M") -> 23274 | AA5: =SUMIFS(QACONDDIA!$D$169:$D$278,QACONDDIA!$E$169:$E$278,"AGUSTINA H") -> 50145 | AB5: =SUMIFS(QACONDDIA!$D$169:$D$278,QACONDDIA!$E$169:$E$278,"NICOLAS Y") -> 37221 | AC5: =Y5+Z5+AA5 -> 78267 | AD5: =AB5 -> 37221
A6: 46115 | B6: TOTAL ENVASADO | G6: TOTAL MASIVO | L6: TOTAL PREMIUM | Q6: MES MÁS PROD. | W6: MAYO | X6: =SUMIFS(QACONDDIA!$D$281:$D$420,QACONDDIA!$E$281:$E$420,"<>") -> 128099 | Y6: =SUMIFS(QACONDDIA!$D$281:$D$412,QACONDDIA!$E$281:$E$412,"JOAQUIN") -> 24158 | Z6: =SUMIFS(QACONDDIA!$D$281:$D$412,QACONDDIA!$E$281:$E$412,"NICOLAS M") -> 37293 | AA6: =SUMIFS(QACONDDIA!$D$281:$D$412,QACONDDIA!$E$281:$E$412,"AGUSTINA H") -> 31425 | AB6: =SUMIFS(QACONDDIA!$D$281:$D$412,QACONDDIA!$E$281:$E$412,"NICOLAS Y") -> 32007 | AC6: =Y6+Z6+AA6 -> 92876 | AD6: =AB6 -> 32007
A7: 46143 | B7: =X18 -> 462933 | G7: =AC11 -> 321573 | L7: =AD11 -> 136944 | Q7: =X12 -> MAYO | W7: JUNIO | X7: =SUMIFS(QACONDDIA!$D$420:$D$600,QACONDDIA!$E$420:$E$600,"<>") -> 104858 | Y7: =SUMIFS(QACONDDIA!$D$433:$D$600,QACONDDIA!$E$433:$E$600,"JOAQUIN") -> 21778 | Z7: =SUMIFS(QACONDDIA!$D$433:$D$600,QACONDDIA!$E$433:$E$600,"NICOLAS M") -> 22066 | AA7: =SUMIFS(QACONDDIA!$D$433:$D$600,QACONDDIA!$E$433:$E$600,"AGUSTINA H") -> 29766 | AB7: =SUMIFS(QACONDDIA!$D$433:$D$600,QACONDDIA!$E$433:$E$600,"NICOLAS Y") -> 30048 | AC7: =Y7+Z7+AA7 -> 73610 | AD7: =AB7 -> 30048
A8: 46167 | W8: JULIO
A9: 46193 | W9: AGOSTO
A10: 46212 | B10: 💎 | H10: 📊 | O10: 📈
A11: 46251 | B11: % PREMIUM | H11: % MASIVO (C. MASIVO) | O11: PROMEDIO DIARIO | W11: Maximo | X11: =max(X3:X7) -> 128099 | Y11: =SUM(Y3:Y10) -> 72817 | Z11: =SUM(Z3:Z10) -> 114694 | AA11: =SUM(AA3:AA10) -> 134062 | AB11: =SUM(AB3:AB10) -> 136944 | AC11: =SUM(AC3:AC10) -> 321573 | AD11: =SUM(AD3:AD10) -> 136944
A12: 46307 | B12: =IFERROR(AD11/X18,0) -> 0.29581819 | H12: =IFERROR(AC11/X18,0) -> 0.69464264 | O12: =IFERROR(X18/NETWORKDAYS(DATE(2026,1,1),TODAY(),A1:A29),0) -> 4096.7522 | W12: MES_MAX | X12: {=INDEX(W3:W6,MATCH(MAX(X3:X6),X3:X6,0))} -> MAYO
A13: 46346 | W13: JOAQUIN | X13: =Y11 -> 72817
A14: 46364 | W14: NICOLAS M | X14: =Z11 -> 114694
A15: 46381 | W15: AGUSTINA H | X15: =AA11 -> 134062
A16: 46055 | W16: NICOLAS Y | X16: =AB11 -> 136944
A17: 46056 | B17: ▌ INSIGHTS & ALERTAS AUTOMÁTICAS
A18: 46057 | B18: 🏆 MAYOR PRODUCTIVIDAD | I18: ⚠️ MENOR PRODUCTIVIDAD | P18: 📅 MES MÁS PRODUCTIVO | W18: TOTAL | X18: =SUM(X3:X10) -> 462933
A19: 46058 | B19: =IFERROR(IFERROR(IF(AND(Y11>=Z11,Y11>=AA11,Y11>=AB11),"JOAQUIN",IF(AND(Z11>=AA11,Z11>=AB11),"NICOLAS M",IF(AA11>=AB11,"AGUSTINA H","NICOLAS Y"))),"—")&" | "&TEXT(MAX(Y11,Z11,AA11,AB11),"#,##0")&" un.","—") -> NICOLAS Y | 136,944 un. | I19: =IFERROR(IFERROR(IF(AND(Y11<=Z11,Y11<=AA11,Y11<=AB11),"JOAQUIN",IF(AND(Z11<=AA11,Z11<=AB11),"NICOLAS M",IF(AA11<=AB11,"AGUSTINA H","NICOLAS Y"))),"—")&" | "&TEXT(MIN(Y11,Z11,AA11,AB11),"#,##0")&" un.","—") -> JOAQUIN | 72,817 un. | P19: =IFERROR(X12&" | "&TEXT(X11,"#,##0")&" unidades","—") -> MAYO | 128,099 unidades
A20: 46059
A21: 46062
A22: 46063
A23: 46064
A24: 46065 | B24: 📊 PARTICIPACIÓN MASIVO | I24: 💎 PARTICIPACIÓN PREMIUM | P24: 🚨 ALERTA PREMIUM
A25: 46066 | B25: =IFERROR(TEXT(AC11/X18,"0.0%")&" del total | "&TEXT(AC11,"#,##0")&" unidades","—") -> 69.5% del total | 321,573 unidades | I25: =IFERROR(TEXT(AD11/X18,"0.0%")&" del total | "&TEXT(AD11,"#,##0")&" unidades","—") -> 29.6% del total | 136,944 unidades | P25: =IFERROR(IF(AD11/X11<0,15,"⚠️ PREMIUM BAJO < 15% — Revisar asignación","✅ PREMIUM en nivel aceptable"),"—") -> —
A26: 46286
A27: 46363
A28: 46364
A29: 46381
B30: TENDENCIA MENSUAL COMPARATIVA — VARIACIÓN vs MES ANTERIOR
B31: MES | D31: TOTAL UND. | F31: vs ANTERIOR | H31: VAR. % | J31: JOAQUIN | L31: NICOLAS M | N31: AGUSTINA H | P31: NICOLAS Y | R31: TENDENCIA
B32: FEBRERO | D32: =X3 -> 30285 | F32: — | H32: — | J32: =Y3 -> 8210 | L32: =Z3 -> 6113 | N32: =AA3 -> 7981 | P32: =AB3 -> 7981 | R32: —
B33: MARZO | D33: =X4 -> 84203 | F33: =IFERROR(X4-X3,"—") -> 53918 | H33: =IFERROR((X4-X3)/X3,"—") -> 1.7803533 | J33: =Y4 -> 13823 | L33: =Z4 -> 25948 | N33: =AA4 -> 14745 | P33: =AB4 -> 29687 | R33: =IFERROR(IF(X4>X3,"↑ SUBE","↓ BAJA"),"—") -> ↑ SUBE
B34: ABRIL | D34: =X5 -> 115488 | F34: =IFERROR(X5-X4,"—") -> 31285 | H34: =IFERROR((X5-X4)/X4,"—") -> 0.37154258 | J34: =Y5 -> 4848 | L34: =Z5 -> 23274 | N34: =AA5 -> 50145 | P34: =AB5 -> 37221 | R34: =IFERROR(IF(X5>X4,"↑ SUBE","↓ BAJA"),"—") -> ↑ SUBE
B35: MAYO | D35: =X6 -> 128099 | F35: =IFERROR(X6-X5,"—") -> 12611 | H35: =IFERROR((X6-X5)/X5,"—") -> 0.10919749 | J35: =Y6 -> 24158 | L35: =Z6 -> 37293 | N35: =AA6 -> 31425 | P35: =AB6 -> 32007 | R35: =IFERROR(IF(X6>X5,"↑ SUBE","↓ BAJA"),"—") -> ↑ SUBE
B36: JUNIO | D36: =X7 -> 104858 | F36: =IFERROR(X7-X6,"—") -> -23241 | H36: =IFERROR((X7-X6)/X6,"—") -> -0.18142999 | J36: =Y7 -> 21778 | L36: =Z7 -> 22066 | N36: =AA7 -> 29766 | P36: =AB7 -> 30048 | R36: =IFERROR(IF(X7>X6,"↑ SUBE","↓ BAJA"),"—") -> ↓ BAJA
B39: TOTAL ACUM. | D39: =X11 -> 128099 | J39: =Y11 -> 72817 | L39: =Z11 -> 114694 | N39: =AA11 -> 134062 | P39: =AB11 -> 136944
J40: =J39/ SUM(J39:Q39) -> 0.15880982 | L40: =L39/ SUM(J39:S39) -> 0.25014122 | N40: =N39/ SUM(J39:U39) -> 0.29238174 | P40: =P39/ SUM(L39:W39) -> 0.35505315
